Workbook

Sheet Resumen
B2: Escenario 1 - Con Préstamos | I2: Escenario 2 - Con Fondos Propios | P2: Escenario 3 - Con Fondos de Inversión | W2: Escenario 4 - Con Aumento del Factor Multiplicador
A3: Año | B3: Tarifa (USD/kW mes) | C3: Deuda (MMUSD) | D3: SCE (MMUSD) | E3: RSA (MMUSD) | F3: Fondo (MMUSD) | I3: Tarifa (USD/kW mes) | J3: Deuda (MMUSD) | K3: SCE (MMUSD) | L3: RSA (MMUSD) | M3: Fondo (MMUSD) | P3: Tarifa (USD/kW mes) | Q3: Deuda (MMUSD) | R3: SCE (MMUSD) | S3: RSA (MMUSD) | T3: Fondo (MMUSD) | W3: Tarifa (USD/kW mes) | X3: Deuda (MMUSD) | Y3: SCE (MMUSD) | Z3: RSA (MMUSD) | AA3: Fondo (MMUSD)
A4: 2026 | B4: =+'Esc. 1 - Préstamos'!G33 -> 19.279812 | C4: =+'Esc. 1 - Préstamos'!G23 -> 26.7 | D4: =+-'Esc. 1 - Préstamos'!J28 -> #REF! | E4: =+'Esc. 1 - Préstamos'!G25 -> 1300 | F4: =+'Esc. 1 - Préstamos'!G25+'Esc. 1 - Préstamos'!G27 -> 1300 | H4: 2026 | I4: =+'Esc. 2 - F. Propios'!G33 -> 19.279812 | J4: =+'Esc. 2 - F. Propios'!G23 -> 26.7 | K4: =+-('Esc. 2 - F. Propios'!G28) -> 27.3 | L4: =+'Esc. 2 - F. Propios'!G25 -> 1300 | M4: =+'Esc. 2 - F. Propios'!G25+'Esc. 2 - F. Propios'!G27 -> 1300 | O4: 2026 | P4: =+'Esc. 3 - F. Acumulable'!G33 -> 19.279812 | Q4: =+'Esc. 3 - F. Acumulable'!G23 -> 26.7 | R4: =+-('Esc. 3 - F. Acumulable'!G28) -> 27.3 | S4: =+'Esc. 3 - F. Acumulable'!G25 -> 1300 | T4: =+'Esc. 3 - F. Acumulable'!G16 -> 1300 | V4: 2026 | W4: =+'Esc. 4 - F. Multiplicador'!G33 -> 19.279812 | X4: =+'Esc. 4 - F. Multiplicador'!G23 -> 26.7 | Y4: =+-'Esc. 4 - F. Multiplicador'!G28 -> 27.3 | Z4: =+'Esc. 4 - F. Multiplicador'!G25 -> 1300 | AA4: =+'Esc. 4 - F. Multiplicador'!G16 -> 1300
A5: 2027 | B5: =+'Esc. 1 - Préstamos'!J33 -> #REF! | C5: =+'Esc. 1 - Préstamos'!J23 -> 61.7 | D5: =+-'Esc. 1 - Préstamos'!J28 -> #REF! | E5: =+'Esc. 1 - Préstamos'!J25 -> 400 | F5: =+'Esc. 1 - Préstamos'!J25+'Esc. 1 - Préstamos'!J27 -> 400 | H5: 2027 | I5: =+'Esc. 2 - F. Propios'!J33 -> #REF! | J5: =+'Esc. 2 - F. Propios'!J23 -> 23.3 | K5: =+-('Esc. 2 - F. Propios'!J28) -> #REF! | L5: =+'Esc. 2 - F. Propios'!J25 -> 400 | M5: =+'Esc. 2 - F. Propios'!J25+'Esc. 2 - F. Propios'!J27 -> 902 | O5: 2027 | P5: =+'Esc. 3 - F. Acumulable'!J33 -> #REF! | Q5: =+'Esc. 3 - F. Acumulable'!J23 -> 23.3 | R5: =+-('Esc. 3 - F. Acumulable'!J28) -> #REF! | S5: =+'Esc. 3 - F. Acumulable'!J25 -> 200 | T5: =+'Esc. 3 - F. Acumulable'!J16 -> 514 | V5: 2027 | W5: =+'Esc. 4 - F. Multiplicador'!J33 -> 17.460203 | X5: =+'Esc. 4 - F. Multiplicador'!J23 -> 23.3 | Y5: =+-'Esc. 4 - F. Multiplicador'!J28 -> 0 | Z5: =+'Esc. 4 - F. Multiplicador'!J25 -> 250 | AA5: =+'Esc. 4 - F. Multiplicador'!J16 -> 250
A6: 2028 | B6: =+'Esc. 1 - Préstamos'!M33 -> #REF! | C6: =+'Esc. 1 - Préstamos'!M23 -> 121.3 | D6: =+-'Esc. 1 - Préstamos'!M28 -> #REF! | E6: =+'Esc. 1 - Préstamos'!M25 -> 300 | F6: =+'Esc. 1 - Préstamos'!M25+'Esc. 1 - Préstamos'!M27 -> 300 | H6: 2028 | I6: =+'Esc. 2 - F. Propios'!M33 -> #REF! | J6: =+'Esc. 2 - F. Propios'!M23 -> 17.2 | K6: =+-('Esc. 2 - F. Propios'!M28) -> #REF! | L6: =+'Esc. 2 - F. Propios'!M25 -> 300 | M6: =+'Esc. 2 - F. Propios'!M25+'Esc. 2 - F. Propios'!M27 -> 1158 | O6: 2028 | P6: =+'Esc. 3 - F. Acumulable'!M33 -> #REF! | Q6: =+'Esc. 3 - F. Acumulable'!M23 -> 17.2 | R6: =+-('Esc. 3 - F. Acumulable'!M28) -> #REF! | S6: =+'Esc. 3 - F. Acumulable'!M25 -> 200 | T6: =+'Esc. 3 - F. Acumulable'!M16 -> 514 | V6: 2028 | W6: =+'Esc. 4 - F. Multiplicador'!M33 -> 16.477435 | X6: =+'Esc. 4 - F. Multiplicador'!M23 -> 17.2 | Y6: =+-'Esc. 4 - F. Multiplicador'!M28 -> 0 | Z6: =+'Esc. 4 - F. Multiplicador'!M25 -> 100 | AA6: =+'Esc. 4 - F. Multiplicador'!M16 -> 100
A7: 2029 | B7: =+'Esc. 1 - Préstamos'!P33 -> #REF! | C7: =+'Esc. 1 - Préstamos'!P23 -> 233.1 | D7: =+-'Esc. 1 - Préstamos'!P28 -> #REF! | E7: =+'Esc. 1 - Préstamos'!P25 -> 200 | F7: =+'Esc. 1 - Préstamos'!P25+'Esc. 1 - Préstamos'!P27 -> 200 | H7: 2029 | I7: =+'Esc. 2 - F. Propios'!P33 -> #REF! | J7: =+'Esc. 2 - F. Propios'!P23 -> 17.2 | K7: =+-('Esc. 2 - F. Propios'!P28) -> #REF! | L7: =+'Esc. 2 - F. Propios'!P25 -> 200 | M7: =+'Esc. 2 - F. Propios'!P25+'Esc. 2 - F. Propios'!P27 -> 1660 | O7: 2029 | P7: =+'Esc. 3 - F. Acumulable'!P33 -> #REF! | Q7: =+'Esc. 3 - F. Acumulable'!P23 -> 17.2 | R7: =+-('Esc. 3 - F. Acumulable'!P28) -> #REF! | S7: =+'Esc. 3 - F. Acumulable'!P25 -> 200 | T7: =+'Esc. 3 - F. Acumulable'!P16 -> 514 | V7: 2029 | W7: =+'Esc. 4 - F. Multiplicador'!P33 -> 16.519524 | X7: =+'Esc. 4 - F. Multiplicador'!P23 -> 17.2 | Y7: =+-'Esc. 4 - F. Multiplicador'!P28 -> 0 | Z7: =+'Esc. 4 - F. Multiplicador'!P25 -> 100 | AA7: =+'Esc. 4 - F. Multiplicador'!P16 -> 100
A8: 2030 | B8: =+'Esc. 1 - Préstamos'!S33 -> #REF! | C8: =+'Esc. 1 - Préstamos'!S23 -> 377.1 | D8: =+-'Esc. 1 - Préstamos'!S28 -> #REF! | E8: =+'Esc. 1 - Préstamos'!S25 -> 100 | F8: =+'Esc. 1 - Préstamos'!S25+'Esc. 1 - Préstamos'!S27 -> 100 | H8: 2030 | I8: =+'Esc. 2 - F. Propios'!S33 -> #REF! | J8: =+'Esc. 2 - F. Propios'!S23 -> 17.2 | K8: =+-('Esc. 2 - F. Propios'!S28) -> #REF! | L8: =+'Esc. 2 - F. Propios'!S25 -> 100 | M8: =+'Esc. 2 - F. Propios'!S25+'Esc. 2 - F. Propios'!S27 -> 1980 | O8: 2030 | P8: =+'Esc. 3 - F. Acumulable'!S33 -> #REF! | Q8: =+'Esc. 3 - F. Acumulable'!S23 -> 17.2 | R8: =+-('Esc. 3 - F. Acumulable'!S28) -> #REF! | S8: =+'Esc. 3 - F. Acumulable'!S25 -> 200 | T8: =+'Esc. 3 - F. Acumulable'!S16 -> 514 | V8: 2030 | W8: =+'Esc. 4 - F. Multiplicador'!S33 -> 16.58588 | X8: =+'Esc. 4 - F. Multiplicador'!S23 -> 17.2 | Y8: =+-'Esc. 4 - F. Multiplicador'!S28 -> 0 | Z8: =+'Esc. 4 - F. Multiplicador'!S25 -> 100 | AA8: =+'Esc. 4 - F. Multiplicador'!S16 -> 100
A9: 2031 | B9: =+'Esc. 1 - Préstamos'!V33 -> #REF! | C9: =+'Esc. 1 - Préstamos'!V23 -> 522.6 | D9: =+-'Esc. 1 - Préstamos'!V28 -> #REF! | E9: =+'Esc. 1 - Préstamos'!V25 -> 100 | F9: =+'Esc. 1 - Préstamos'!V25+'Esc. 1 - Préstamos'!V27 -> 100 | H9: 2031 | I9: =+'Esc. 2 - F. Propios'!V33 -> #REF! | J9: =+'Esc. 2 - F. Propios'!V23 -> 17.2 | K9: =+-('Esc. 2 - F. Propios'!V28) -> #REF! | L9: =+'Esc. 2 - F. Propios'!V25 -> 100 | M9: =+'Esc. 2 - F. Propios'!V25+'Esc. 2 - F. Propios'!V27 -> 2000 | O9: 2031 | P9: =+'Esc. 3 - F. Acumulable'!V33 -> #REF! | Q9: =+'Esc. 3 - F. Acumulable'!V23 -> 17.2 | R9: =+-('Esc. 3 - F. Acumulable'!V28) -> #REF! | S9: =+'Esc. 3 - F. Acumulable'!V25 -> 200 | T9: =+'Esc. 3 - F. Acumulable'!V16 -> 514 | V9: 2031 | W9: =+'Esc. 4 - F. Multiplicador'!V33 -> 16.652715 | X9: =+'Esc. 4 - F. Multiplicador'!V23 -> 17.2 | Y9: =+-'Esc. 4 - F. Multiplicador'!V28 -> 0 | Z9: =+'Esc. 4 - F. Multiplicador'!V25 -> 100 | AA9: =+'Esc. 4 - F. Multiplicador'!V16 -> 100
A10: 2032 | B10: =+'Esc. 1 - Préstamos'!Y33 -> #REF! | C10: =+'Esc. 1 - Préstamos'!Y23 -> 660.4 | D10: =+-'Esc. 1 - Préstamos'!Y28 -> #REF! | E10: =+'Esc. 1 - Préstamos'!Y25 -> 100 | F10: =+'Esc. 1 - Préstamos'!Y25+'Esc. 1 - Préstamos'!Y27 -> 100 | H10: 2032 | I10: =+'Esc. 2 - F. Propios'!Y33 -> #REF! | J10: =+'Esc. 2 - F. Propios'!Y23 -> 17.2 | K10: =+-('Esc. 2 - F. Propios'!Y28) -> #REF! | L10: =+'Esc. 2 - F. Propios'!Y25 -> 100 | M10: =+'Esc. 2 - F. Propios'!Y25+'Esc. 2 - F. Propios'!Y27 -> 1900 | O10: 2032 | P10: =+'Esc. 3 - F. Acumulable'!Y33 -> #REF! | Q10: =+'Esc. 3 - F. Acumulable'!Y23 -> 17.2 | R10: =+-('Esc. 3 - F. Acumulable'!Y28) -> #REF! | S10: =+'Esc. 3 - F. Acumulable'!Y25 -> 200 | T10: =+'Esc. 3 - F. Acumulable'!Y16 -> 514 | V10: 2032 | W10: =+'Esc. 4 - F. Multiplicador'!Y33 -> 16.744519 | X10: =+'Esc. 4 - F. Multiplicador'!Y23 -> 17.2 | Y10: =+-'Esc. 4 - F. Multiplicador'!Y28 -> 0 | Z10: =+'Esc. 4 - F. Multiplicador'!Y25 -> 100 | AA10: =+'Esc. 4 - F. Multiplicador'!Y16 -> 100
A11: 2033 | B11: =+'Esc. 1 - Préstamos'!AB33 -> #REF! | C11: =+'Esc. 1 - Préstamos'!AB23 -> 798.2 | D11: =+-'Esc. 1 - Préstamos'!AB28 -> #REF! | E11: =+'Esc. 1 - Préstamos'!AB25 -> 100 | F11: =+'Esc. 1 - Préstamos'!AB25+'Esc. 1 - Préstamos'!AB27 -> 100 | H11: 2033 | I11: =+'Esc. 2 - F. Propios'!AB33 -> #REF! | J11: =+'Esc. 2 - F. Propios'!AB23 -> 17.2 | K11: =+-('Esc. 2 - F. Propios'!AB28) -> #REF! | L11: =+'Esc. 2 - F. Propios'!AB25 -> 100 | M11: =+'Esc. 2 - F. Propios'!AB25+'Esc. 2 - F. Propios'!AB27 -> 1900 | O11: 2033 | P11: =+'Esc. 3 - F. Acumulable'!AB33 -> #REF! | Q11: =+'Esc. 3 - F. Acumulable'!AB23 -> 17.2 | R11: =+-('Esc. 3 - F. Acumulable'!AB28) -> #REF! | S11: =+'Esc. 3 - F. Acumulable'!AB25 -> 200 | T11: =+'Esc. 3 - F. Acumulable'!AB16 -> 514 | V11: 2033 | W11: =+'Esc. 4 - F. Multiplicador'!AB33 -> 16.787837 | X11: =+'Esc. 4 - F. Multiplicador'!AB23 -> 17.2 | Y11: =+-'Esc. 4 - F. Multiplicador'!AB28 -> 0 | Z11: =+'Esc. 4 - F. Multiplicador'!AB25 -> 100 | AA11: =+'Esc. 4 - F. Multiplicador'!AB16 -> 100
A12: 2034 | B12: =+'Esc. 1 - Préstamos'!AE33 -> #REF! | C12: =+'Esc. 1 - Préstamos'!AE23 -> 821.2 | D12: =+-'Esc. 1 - Préstamos'!AE28 -> #REF! | E12: =+'Esc. 1 - Préstamos'!AE25 -> 100 | F12: =+'Esc. 1 - Préstamos'!AE25+'Esc. 1 - Préstamos'!AE27 -> 100 | H12: 2034 | I12: =+'Esc. 2 - F. Propios'!AE33 -> #REF! | J12: =+'Esc. 2 - F. Propios'!AE23 -> 17.2 | K12: =+-('Esc. 2 - F. Propios'!AE28) -> #REF! | L12: =+'Esc. 2 - F. Propios'!AE25 -> 100 | M12: =+'Esc. 2 - F. Propios'!AE25+'Esc. 2 - F. Propios'!AE27 -> 400 | O12: 2034 | P12: =+'Esc. 3 - F. Acumulable'!AE33 -> #REF! | Q12: =+'Esc. 3 - F. Acumulable'!AE23 -> 17.2 | R12: =+-('Esc. 3 - F. Acumulable'!AE28) -> #REF! | S12: =+'Esc. 3 - F. Acumulable'!AE25 -> 200 | T12: =+'Esc. 3 - F. Acumulable'!AE16 -> 514 | V12: 2034 | W12: =+'Esc. 4 - F. Multiplicador'!AE33 -> 16.85613 | X12: =+'Esc. 4 - F. Multiplicador'!AE23 -> 17.2 | Y12: =+-'Esc. 4 - F. Multiplicador'!AE28 -> 0 | Z12: =+'Esc. 4 - F. Multiplicador'!AE25 -> 100 | AA12: =+'Esc. 4 - F. Multiplicador'!AE16 -> 100
A13: 2035 | B13: =+'Esc. 1 - Préstamos'!AH33 -> #REF! | C13: =+'Esc. 1 - Préstamos'!AH23 -> 821.2 | D13: =+-'Esc. 1 - Préstamos'!AH28 -> #REF! | E13: =+'Esc. 1 - Préstamos'!AH25 -> 100 | F13: =+'Esc. 1 - Préstamos'!AH25+'Esc. 1 - Préstamos'!AH27 -> 100 | H13: 2035 | I13: =+'Esc. 2 - F. Propios'!AH33 -> #REF! | J13: =+'Esc. 2 - F. Propios'!AH23 -> 17.2 | K13: =+-('Esc. 2 - F. Propios'!AH28) -> #REF! | L13: =+'Esc. 2 - F. Propios'!AH25 -> 100 | M13: =+'Esc. 2 - F. Propios'!AH25+'Esc. 2 - F. Propios'!AH27 -> 100 | O13: 2035 | P13: =+'Esc. 3 - F. Acumulable'!AH33 -> #REF! | Q13: =+'Esc. 3 - F. Acumulable'!AH23 -> 17.2 | R13: =+-('Esc. 3 - F. Acumulable'!AH28) -> #REF! | S13: =+'Esc. 3 - F. Acumulable'!AH25 -> 200 | T13: =+'Esc. 3 - F. Acumulable'!AH16 -> 514 | V13: 2035 | W13: =+'Esc. 4 - F. Multiplicador'!AH33 -> 16.924916 | X13: =+'Esc. 4 - F. Multiplicador'!AH23 -> 17.2 | Y13: =+-'Esc. 4 - F. Multiplicador'!AH28 -> 0 | Z13: =+'Esc. 4 - F. Multiplicador'!AH25 -> 100 | AA13: =+'Esc. 4 - F. Multiplicador'!AH16 -> 100
A14: 2036 | B14: =+'Esc. 1 - Préstamos'!AK33 -> #REF! | C14: =+'Esc. 1 - Préstamos'!AK23 -> 821.2 | D14: =+-'Esc. 1 - Préstamos'!AK28 -> #REF! | E14: =+'Esc. 1 - Préstamos'!AK25 -> 100 | F14: =+'Esc. 1 - Préstamos'!AK25+'Esc. 1 - Préstamos'!AK27 -> 100 | H14: 2036 | I14: =+'Esc. 2 - F. Propios'!AK33 -> #REF! | J14: =+'Esc. 2 - F. Propios'!AK23 -> 17.2 | K14: =+-('Esc. 2 - F. Propios'!AK28) -> #REF! | L14: =+'Esc. 2 - F. Propios'!AK25 -> 100 | M14: =+'Esc. 2 - F. Propios'!AK25+'Esc. 2 - F. Propios'!AK27 -> 100 | O14: 2036 | P14: =+'Esc. 3 - F. Acumulable'!AK33 -> #REF! | Q14: =+'Esc. 3 - F. Acumulable'!AK23 -> 17.2 | R14: =+-('Esc. 3 - F. Acumulable'!AK28) -> #REF! | S14: =+'Esc. 3 - F. Acumulable'!AK25 -> 200 | T14: =+'Esc. 3 - F. Acumulable'!AK16 -> 514 | V14: 2036 | W14: =+'Esc. 4 - F. Multiplicador'!AK33 -> 17.0194 | X14: =+'Esc. 4 - F. Multiplicador'!AK23 -> 17.2 | Y14: =+-'Esc. 4 - F. Multiplicador'!AK28 -> 0 | Z14: =+'Esc. 4 - F. Multiplicador'!AK25 -> 100 | AA14: =+'Esc. 4 - F. Multiplicador'!AK16 -> 100
A15: 2037 | B15: =+'Esc. 1 - Préstamos'!AN33 -> #REF! | C15: =+'Esc. 1 - Préstamos'!AN23 -> 821.2 | D15: =+-'Esc. 1 - Préstamos'!AN28 -> #REF! | E15: =+'Esc. 1 - Préstamos'!AN25 -> 100 | F15: =+'Esc. 1 - Préstamos'!AN25+'Esc. 1 - Préstamos'!AN27 -> 100 | H15: 2037 | I15: =+'Esc. 2 - F. Propios'!AN33 -> #REF! | J15: =+'Esc. 2 - F. Propios'!AN23 -> 17.2 | K15: =+-('Esc. 2 - F. Propios'!AN28) -> #REF! | L15: =+'Esc. 2 - F. Propios'!AN25 -> 100 | M15: =+'Esc. 2 - F. Propios'!AN25+'Esc. 2 - F. Propios'!AN27 -> 100 | O15: 2037 | P15: =+'Esc. 3 - F. Acumulable'!AN33 -> #REF! | Q15: =+'Esc. 3 - F. Acumulable'!AN23 -> 17.2 | R15: =+-('Esc. 3 - F. Acumulable'!AN28) -> #REF! | S15: =+'Esc. 3 - F. Acumulable'!AN25 -> 200 | T15: =+'Esc. 3 - F. Acumulable'!AN16 -> 514 | V15: 2037 | W15: =+'Esc. 4 - F. Multiplicador'!AN33 -> 18.43742 | X15: =+'Esc. 4 - F. Multiplicador'!AN23 -> 17.2 | Y15: =+-'Esc. 4 - F. Multiplicador'!AN28 -> 0 | Z15: =+'Esc. 4 - F. Multiplicador'!AN25 -> 100 | AA15: =+'Esc. 4 - F. Multiplicador'!AN16 -> 100
A16: 2038 | B16: =+'Esc. 1 - Préstamos'!AQ33 -> #REF! | C16: =+'Esc. 1 - Préstamos'!AQ23 -> 821.2 | D16: =+-'Esc. 1 - Préstamos'!AQ28 -> #REF! | E16: =+'Esc. 1 - Préstamos'!AQ25 -> 100 | F16: =+'Esc. 1 - Préstamos'!AQ25+'Esc. 1 - Préstamos'!AQ27 -> 100 | H16: 2038 | I16: =+'Esc. 2 - F. Propios'!AQ33 -> #REF! | J16: =+'Esc. 2 - F. Propios'!AQ23 -> 17.2 | K16: =+-('Esc. 2 - F. Propios'!AQ28) -> #REF! | L16: =+'Esc. 2 - F. Propios'!AQ25 -> 100 | M16: =+'Esc. 2 - F. Propios'!AQ25+'Esc. 2 - F. Propios'!AQ27 -> 100 | O16: 2038 | P16: =+'Esc. 3 - F. Acumulable'!AQ33 -> #REF! | Q16: =+'Esc. 3 - F. Acumulable'!AQ23 -> 17.2 | R16: =+-('Esc. 3 - F. Acumulable'!AQ28) -> #REF! | S16: =+'Esc. 3 - F. Acumulable'!AQ25 -> 200 | T16: =+'Esc. 3 - F. Acumulable'!AQ16 -> 514 | V16: 2038 | W16: =+'Esc. 4 - F. Multiplicador'!AQ33 -> 18.386494 | X16: =+'Esc. 4 - F. Multiplicador'!AQ23 -> 17.2 | Y16: =+-'Esc. 4 - F. Multiplicador'!AQ28 -> 0 | Z16: =+'Esc. 4 - F. Multiplicador'!AQ25 -> 100 | AA16: =+'Esc. 4 - F. Multiplicador'!AQ16 -> 100
A17: 2039 | B17: =+'Esc. 1 - Préstamos'!AT33 -> #REF! | C17: =+'Esc. 1 - Préstamos'!AT23 -> 804 | D17: =+-'Esc. 1 - Préstamos'!AT28 -> #REF! | E17: =+'Esc. 1 - Préstamos'!AT25 -> 100 | F17: =+'Esc. 1 - Préstamos'!AT25+'Esc. 1 - Préstamos'!AT27 -> 100 | H17: 2039 | I17: =+'Esc. 2 - F. Propios'!AT33 -> #REF! | J17: =+'Esc. 2 - F. Propios'!AT23 -> 0 | K17: =+-('Esc. 2 - F. Propios'!AT28) -> #REF! | L17: =+'Esc. 2 - F. Propios'!AT25 -> 100 | M17: =+'Esc. 2 - F. Propios'!AT25+'Esc. 2 - F. Propios'!AT27 -> 100 | O17: 2039 | P17: =+'Esc. 3 - F. Acumulable'!AT33 -> #REF! | Q17: =+'Esc. 3 - F. Acumulable'!AT23 -> 0 | R17: =+-('Esc. 3 - F. Acumulable'!AT28) -> #REF! | S17: =+'Esc. 3 - F. Acumulable'!AT25 -> 200 | T17: =+'Esc. 3 - F. Acumulable'!AT16 -> 514 | V17: 2039 | W17: =+'Esc. 4 - F. Multiplicador'!AT33 -> 18.220154 | X17: =+'Esc. 4 - F. Multiplicador'!AT23 -> 0 | Y17: =+-'Esc. 4 - F. Multiplicador'!AT28 -> 0 | Z17: =+'Esc. 4 - F. Multiplicador'!AT25 -> 100 | AA17: =+'Esc. 4 - F. Multiplicador'!AT16 -> 100
A18: 2040 | B18: =+'Esc. 1 - Préstamos'!AW33 -> #REF! | C18: =+'Esc. 1 - Préstamos'!AW23 -> 804 | D18: =+-'Esc. 1 - Préstamos'!AW28 -> #REF! | E18: =+'Esc. 1 - Préstamos'!AW25 -> 100 | F18: =+'Esc. 1 - Préstamos'!AW25+'Esc. 1 - Préstamos'!AW27 -> 100 | H18: 2040 | I18: =+'Esc. 2 - F. Propios'!AW33 -> #REF! | J18: =+'Esc. 2 - F. Propios'!AW23 -> 0 | K18: =+-('Esc. 2 - F. Propios'!AW28) -> #REF! | L18: =+'Esc. 2 - F. Propios'!AW25 -> 100 | M18: =+'Esc. 2 - F. Propios'!AW25+'Esc. 2 - F. Propios'!AW27 -> 100 | O18: 2040 | P18: =+'Esc. 3 - F. Acumulable'!AW33 -> #REF! | Q18: =+'Esc. 3 - F. Acumulable'!AW23 -> 0 | R18: =+-('Esc. 3 - F. Acumulable'!AW28) -> #REF! | S18: =+'Esc. 3 - F. Acumulable'!AW25 -> 200 | T18: =+'Esc. 3 - F. Acumulable'!AW16 -> 514 | V18: 2040 | W18: =+'Esc. 4 - F. Multiplicador'!AW33 -> 18.197723 | X18: =+'Esc. 4 - F. Multiplicador'!AW23 -> 0 | Y18: =+-'Esc. 4 - F. Multiplicador'!AW28 -> 0 | Z18: =+'Esc. 4 - F. Multiplicador'!AW25 -> 100 | AA18: =+'Esc. 4 - F. Multiplicador'!AW16 -> 100
A19: 2041 | B19: =+'Esc. 1 - Préstamos'!AZ33 -> #REF! | C19: =+'Esc. 1 - Préstamos'!AZ23 -> 804 | D19: =+-'Esc. 1 - Préstamos'!AZ28 -> #REF! | E19: =+'Esc. 1 - Préstamos'!AZ25 -> 100 | F19: =+'Esc. 1 - Préstamos'!AZ25+'Esc. 1 - Préstamos'!AZ27 -> 100 | H19: 2041 | I19: =+'Esc. 2 - F. Propios'!AZ33 -> #REF! | J19: =+'Esc. 2 - F. Propios'!AZ23 -> 0 | K19: =+-('Esc. 2 - F. Propios'!AZ28) -> #REF! | L19: =+'Esc. 2 - F. Propios'!AZ25 -> 100 | M19: =+'Esc. 2 - F. Propios'!AZ25+'Esc. 2 - F. Propios'!AZ27 -> 100 | O19: 2041 | P19: =+'Esc. 3 - F. Acumulable'!AZ33 -> #REF! | Q19: =+'Esc. 3 - F. Acumulable'!AZ23 -> 0 | R19: =+-('Esc. 3 - F. Acumulable'!AZ28) -> #REF! | S19: =+'Esc. 3 - F. Acumulable'!AZ25 -> 200 | T19: =+'Esc. 3 - F. Acumulable'!AZ16 -> 514 | V19: 2041 | W19: =+'Esc. 4 - F. Multiplicador'!AZ33 -> 18.125542 | X19: =+'Esc. 4 - F. Multiplicador'!AZ23 -> 0 | Y19: =+-'Esc. 4 - F. Multiplicador'!AZ28 -> 0 | Z19: =+'Esc. 4 - F. Multiplicador'!AZ25 -> 100 | AA19: =+'Esc. 4 - F. Multiplicador'!AZ16 -> 100
A20: 2042 | B20: =+'Esc. 1 - Préstamos'!BC33 -> #REF! | C20: =+'Esc. 1 - Préstamos'!BC23 -> 804 | D20: =+-'Esc. 1 - Préstamos'!BC28 -> #REF! | E20: =+'Esc. 1 - Préstamos'!BC25 -> 100 | F20: =+'Esc. 1 - Préstamos'!BC25+'Esc. 1 - Préstamos'!BC27 -> 100 | H20: 2042 | I20: =+'Esc. 2 - F. Propios'!BC33 -> #REF! | J20: =+'Esc. 2 - F. Propios'!BC23 -> 0 | K20: =+-('Esc. 2 - F. Propios'!BC28) -> #REF! | L20: =+'Esc. 2 - F. Propios'!BC25 -> 100 | M20: =+'Esc. 2 - F. Propios'!BC25+'Esc. 2 - F. Propios'!BC27 -> 100 | O20: 2042 | P20: =+'Esc. 3 - F. Acumulable'!BC33 -> #REF! | Q20: =+'Esc. 3 - F. Acumulable'!BC23 -> 0 | R20: =+-('Esc. 3 - F. Acumulable'!BC28) -> #REF! | S20: =+'Esc. 3 - F. Acumulable'!BC25 -> 200 | T20: =+'Esc. 3 - F. Acumulable'!BC16 -> 514 | V20: 2042 | W20: =+'Esc. 4 - F. Multiplicador'!BC33 -> 18.079893 | X20: =+'Esc. 4 - F. Multiplicador'!BC23 -> 0 | Y20: =+-'Esc. 4 - F. Multiplicador'!BC28 -> 0 | Z20: =+'Esc. 4 - F. Multiplicador'!BC25 -> 100 | AA20: =+'Esc. 4 - F. Multiplicador'!BC16 -> 100
A21: 2043 | B21: =+'Esc. 1 - Préstamos'!BF33 -> #REF! | C21: =+'Esc. 1 - Préstamos'!BF23 -> 804 | D21: =+-'Esc. 1 - Préstamos'!BF28 -> #REF! | E21: =+'Esc. 1 - Préstamos'!BF25 -> 100 | F21: =+'Esc. 1 - Préstamos'!BF25+'Esc. 1 - Préstamos'!BF27 -> 100 | H21: 2043 | I21: =+'Esc. 2 - F. Propios'!BF33 -> #REF! | J21: =+'Esc. 2 - F. Propios'!BF23 -> 0 | K21: =+-('Esc. 2 - F. Propios'!BF28) -> #REF! | L21: =+'Esc. 2 - F. Propios'!BF25 -> 100 | M21: =+'Esc. 2 - F. Propios'!BF25+'Esc. 2 - F. Propios'!BF27 -> 100 | O21: 2043 | P21: =+'Esc. 3 - F. Acumulable'!BF33 -> #REF! | Q21: =+'Esc. 3 - F. Acumulable'!BF23 -> 0 | R21: =+-('Esc. 3 - F. Acumulable'!BF28) -> #REF! | S21: =+'Esc. 3 - F. Acumulable'!BF25 -> 200 | T21: =+'Esc. 3 - F. Acumulable'!BF16 -> 514 | V21: 2043 | W21: =+'Esc. 4 - F. Multiplicador'!BF33 -> 18.035325 | X21: =+'Esc. 4 - F. Multiplicador'!BF23 -> 0 | Y21: =+-'Esc. 4 - F. Multiplicador'!BF28 -> 0 | Z21: =+'Esc. 4 - F. Multiplicador'!BF25 -> 100 | AA21: =+'Esc. 4 - F. Multiplicador'!BF16 -> 100
A22: 2044 | B22: =+'Esc. 1 - Préstamos'!BI33 -> #REF! | C22: =+'Esc. 1 - Préstamos'!BI23 -> 804 | D22: =+-'Esc. 1 - Préstamos'!BI28 -> #REF! | E22: =+'Esc. 1 - Préstamos'!BI25 -> 100 | F22: =+'Esc. 1 - Préstamos'!BI25+'Esc. 1 - Préstamos'!BI27 -> 100 | H22: 2044 | I22: =+'Esc. 2 - F. Propios'!BI33 -> #REF! | J22: =+'Esc. 2 - F. Propios'!BI23 -> 0 | K22: =+-('Esc. 2 - F. Propios'!BI28) -> #REF! | L22: =+'Esc. 2 - F. Propios'!BI25 -> 100 | M22: =+'Esc. 2 - F. Propios'!BI25+'Esc. 2 - F. Propios'!BI27 -> 100 | O22: 2044 | P22: =+'Esc. 3 - F. Acumulable'!BI33 -> #REF! | Q22: =+'Esc. 3 - F. Acumulable'!BI23 -> 0 | R22: =+-('Esc. 3 - F. Acumulable'!BI28) -> #REF! | S22: =+'Esc. 3 - F. Acumulable'!BI25 -> 200 | T22: =+'Esc. 3 - F. Acumulable'!BI16 -> 514 | V22: 2044 | W22: =+'Esc. 4 - F. Multiplicador'!BI33 -> 18.017339 | X22: =+'Esc. 4 - F. Multiplicador'!BI23 -> 0 | Y22: =+-'Esc. 4 - F. Multiplicador'!BI28 -> 0 | Z22: =+'Esc. 4 - F. Multiplicador'!BI25 -> 100 | AA22: =+'Esc. 4 - F. Multiplicador'!BI16 -> 100
A23: 2045 | B23: =+'Esc. 1 - Préstamos'!BL33 -> #REF! | C23: =+'Esc. 1 - Préstamos'!BL23 -> 804 | D23: =+-'Esc. 1 - Préstamos'!BL28 -> #REF! | E23: =+'Esc. 1 - Préstamos'!BL25 -> 100 | F23: =+'Esc. 1 - Préstamos'!BL25+'Esc. 1 - Préstamos'!BL27 -> 100 | H23: 2045 | I23: =+'Esc. 2 - F. Propios'!BL33 -> #REF! | J23: =+'Esc. 2 - F. Propios'!BL23 -> 0 | K23: =+-('Esc. 2 - F. Propios'!BL28) -> #REF! | L23: =+'Esc. 2 - F. Propios'!BL25 -> 100 | M23: =+'Esc. 2 - F. Propios'!BL25+'Esc. 2 - F. Propios'!BL27 -> 100 | O23: 2045 | P23: =+'Esc. 3 - F. Acumulable'!BL33 -> #REF! | Q23: =+'Esc. 3 - F. Acumulable'!BL23 -> 0 | R23: =+-('Esc. 3 - F. Acumulable'!BL28) -> #REF! | S23: =+'Esc. 3 - F. Acumulable'!BL25 -> 200 | T23: =+'Esc. 3 - F. Acumulable'!BL16 -> 514 | V23: 2045 | W23: =+'Esc. 4 - F. Multiplicador'!BL33 -> 17.949367 | X23: =+'Esc. 4 - F. Multiplicador'!BL23 -> 0 | Y23: =+-'Esc. 4 - F. Multiplicador'!BL28 -> 0 | Z23: =+'Esc. 4 - F. Multiplicador'!BL25 -> 100 | AA23: =+'Esc. 4 - F. Multiplicador'!BL16 -> 100
A24: 2046 | B24: =+'Esc. 1 - Préstamos'!BO33 -> #REF! | C24: =+'Esc. 1 - Préstamos'!BO23 -> 804 | D24: =+-'Esc. 1 - Préstamos'!BO28 -> #REF! | E24: =+'Esc. 1 - Préstamos'!BO25 -> 100 | F24: =+'Esc. 1 - Préstamos'!BO25+'Esc. 1 - Préstamos'!BO27 -> 100 | H24: 2046 | I24: =+'Esc. 2 - F. Propios'!BO33 -> #REF! | J24: =+'Esc. 2 - F. Propios'!BO23 -> 0 | K24: =+-('Esc. 2 - F. Propios'!BO28) -> #REF! | L24: =+'Esc. 2 - F. Propios'!BO25 -> 100 | M24: =+'Esc. 2 - F. Propios'!BO25+'Esc. 2 - F. Propios'!BO27 -> 100 | O24: 2046 | P24: =+'Esc. 3 - F. Acumulable'!BO33 -> #REF! | Q24: =+'Esc. 3 - F. Acumulable'!BO23 -> 0 | R24: =+-('Esc. 3 - F. Acumulable'!BO28) -> #REF! | S24: =+'Esc. 3 - F. Acumulable'!BO25 -> 200 | T24: =+'Esc. 3 - F. Acumulable'!BO16 -> 514 | V24: 2046 | W24: =+'Esc. 4 - F. Multiplicador'!BO33 -> 17.907945 | X24: =+'Esc. 4 - F. Multiplicador'!BO23 -> 0 | Y24: =+-'Esc. 4 - F. Multiplicador'!BO28 -> 0 | Z24: =+'Esc. 4 - F. Multiplicador'!BO25 -> 100 | AA24: =+'Esc. 4 - F. Multiplicador'!BO16 -> 100
A25: 2047 | B25: =+'Esc. 1 - Préstamos'!BR33 -> #REF! | C25: =+'Esc. 1 - Préstamos'!BR23 -> 804 | D25: =+-'Esc. 1 - Préstamos'!BR28 -> #REF! | E25: =+'Esc. 1 - Préstamos'!BR25 -> 100 | F25: =+'Esc. 1 - Préstamos'!BR25+'Esc. 1 - Préstamos'!BR27 -> 100 | H25: 2047 | I25: =+'Esc. 2 - F. Propios'!BR33 -> #REF! | J25: =+'Esc. 2 - F. Propios'!BR23 -> 0 | K25: =+-('Esc. 2 - F. Propios'!BR28) -> #REF! | L25: =+'Esc. 2 - F. Propios'!BR25 -> 100 | M25: =+'Esc. 2 - F. Propios'!BR25+'Esc. 2 - F. Propios'!BR27 -> 100 | O25: 2047 | P25: =+'Esc. 3 - F. Acumulable'!BR33 -> #REF! | Q25: =+'Esc. 3 - F. Acumulable'!BR23 -> 0 | R25: =+-('Esc. 3 - F. Acumulable'!BR28) -> #REF! | S25: =+'Esc. 3 - F. Acumulable'!BR25 -> 200 | T25: =+'Esc. 3 - F. Acumulable'!BR16 -> 514 | V25: 2047 | W25: =+'Esc. 4 - F. Multiplicador'!BR33 -> 16.579045 | X25: =+'Esc. 4 - F. Multiplicador'!BR23 -> 0 | Y25: =+-'Esc. 4 - F. Multiplicador'!BR28 -> 0 | Z25: =+'Esc. 4 - F. Multiplicador'!BR25 -> 100 | AA25: =+'Esc. 4 - F. Multiplicador'!BR16 -> 100
A26: 2048 | B26: =+'Esc. 1 - Préstamos'!BU33 -> #REF! | C26: =+'Esc. 1 - Préstamos'!BU23 -> 804 | D26: =+-'Esc. 1 - Préstamos'!BU28 -> #REF! | E26: =+'Esc. 1 - Préstamos'!BU25 -> 100 | F26: =+'Esc. 1 - Préstamos'!BU25+'Esc. 1 - Préstamos'!BU27 -> 100 | H26: 2048 | I26: =+'Esc. 2 - F. Propios'!BU33 -> #REF! | J26: =+'Esc. 2 - F. Propios'!BU23 -> 0 | K26: =+-('Esc. 2 - F. Propios'!BU28) -> #REF! | L26: =+'Esc. 2 - F. Propios'!BU25 -> 100 | M26: =+'Esc. 2 - F. Propios'!BU25+'Esc. 2 - F. Propios'!BU27 -> 100 | O26: 2048 | P26: =+'Esc. 3 - F. Acumulable'!BU33 -> #REF! | Q26: =+'Esc. 3 - F. Acumulable'!BU23 -> 0 | R26: =+-('Esc. 3 - F. Acumulable'!BU28) -> #REF! | S26: =+'Esc. 3 - F. Acumulable'!BU25 -> 200 | T26: =+'Esc. 3 - F. Acumulable'!BU16 -> 514 | V26: 2048 | W26: =+'Esc. 4 - F. Multiplicador'!BU33 -> 16.675677 | X26: =+'Esc. 4 - F. Multiplicador'!BU23 -> 0 | Y26: =+-'Esc. 4 - F. Multiplicador'!BU28 -> 0 | Z26: =+'Esc. 4 - F. Multiplicador'!BU25 -> 100 | AA26: =+'Esc. 4 - F. Multiplicador'!BU16 -> 100
A27: 2049 | B27: =+'Esc. 1 - Préstamos'!BX33 -> #REF! | C27: =+'Esc. 1 - Préstamos'!BX23 -> 804 | D27: =+-'Esc. 1 - Préstamos'!BX28 -> #REF! | E27: =+'Esc. 1 - Préstamos'!BX25 -> 100 | F27: =+'Esc. 1 - Préstamos'!BX25+'Esc. 1 - Préstamos'!BX27 -> 100 | H27: 2049 | I27: =+'Esc. 2 - F. Propios'!BX33 -> #REF! | J27: =+'Esc. 2 - F. Propios'!BX23 -> 0 | K27: =+-('Esc. 2 - F. Propios'!BX28) -> #REF! | L27: =+'Esc. 2 - F. Propios'!BX25 -> 100 | M27: =+'Esc. 2 - F. Propios'!BX25+'Esc. 2 - F. Propios'!BX27 -> 100 | O27: 2049 | P27: =+'Esc. 3 - F. Acumulable'!BX33 -> #REF! | Q27: =+'Esc. 3 - F. Acumulable'!BX23 -> 0 | R27: =+-('Esc. 3 - F. Acumulable'!BX28) -> #REF! | S27: =+'Esc. 3 - F. Acumulable'!BX25 -> 200 | T27: =+'Esc. 3 - F. Acumulable'!BX16 -> 514 | V27: 2049 | W27: =+'Esc. 4 - F. Multiplicador'!BX33 -> 16.721273 | X27: =+'Esc. 4 - F. Multiplicador'!BX23 -> 0 | Y27: =+-'Esc. 4 - F. Multiplicador'!BX28 -> 0 | Z27: =+'Esc. 4 - F. Multiplicador'!BX25 -> 100 | AA27: =+'Esc. 4 - F. Multiplicador'!BX16 -> 100
A28: 2050 | B28: =+'Esc. 1 - Préstamos'!CA33 -> #REF! | C28: =+'Esc. 1 - Préstamos'!CA23 -> 804 | D28: =+-'Esc. 1 - Préstamos'!CA28 -> #REF! | E28: =+'Esc. 1 - Préstamos'!CA25 -> 100 | F28: =+'Esc. 1 - Préstamos'!CA25+'Esc. 1 - Préstamos'!CA27 -> 100 | H28: 2050 | I28: =+'Esc. 2 - F. Propios'!CA33 -> #REF! | J28: =+'Esc. 2 - F. Propios'!CA23 -> 0 | K28: =+-('Esc. 2 - F. Propios'!CA28) -> #REF! | L28: =+'Esc. 2 - F. Propios'!CA25 -> 100 | M28: =+'Esc. 2 - F. Propios'!CA25+'Esc. 2 - F. Propios'!CA27 -> 100 | O28: 2050 | P28: =+'Esc. 3 - F. Acumulable'!CA33 -> #REF! | Q28: =+'Esc. 3 - F. Acumulable'!CA23 -> 0 | R28: =+-('Esc. 3 - F. Acumulable'!CA28) -> #REF! | S28: =+'Esc. 3 - F. Acumulable'!CA25 -> 200 | T28: =+'Esc. 3 - F. Acumulable'!CA16 -> 514 | V28: 2050 | W28: =+'Esc. 4 - F. Multiplicador'!CA33 -> 16.793158 | X28: =+'Esc. 4 - F. Multiplicador'!CA23 -> 0 | Y28: =+-'Esc. 4 - F. Multiplicador'!CA28 -> 0 | Z28: =+'Esc. 4 - F. Multiplicador'!CA25 -> 100 | AA28: =+'Esc. 4 - F. Multiplicador'!CA16 -> 100
A29: 2051 | B29: =+'Esc. 1 - Préstamos'!CD33 -> #REF! | C29: =+'Esc. 1 - Préstamos'!CD23 -> 804 | D29: =+-'Esc. 1 - Préstamos'!CD28 -> #REF! | E29: =+'Esc. 1 - Préstamos'!CD25 -> 100 | F29: =+'Esc. 1 - Préstamos'!CD25+'Esc. 1 - Préstamos'!CD27 -> 100 | H29: 2051 | I29: =+'Esc. 2 - F. Propios'!CD33 -> #REF! | J29: =+'Esc. 2 - F. Propios'!CD23 -> 0 | K29: =+-('Esc. 2 - F. Propios'!CD28) -> #REF! | L29: =+'Esc. 2 - F. Propios'!CD25 -> 100 | M29: =+'Esc. 2 - F. Propios'!CD25+'Esc. 2 - F. Propios'!CD27 -> 100 | O29: 2051 | P29: =+'Esc. 3 - F. Acumulable'!CD33 -> #REF! | Q29: =+'Esc. 3 - F. Acumulable'!CD23 -> 0 | R29: =+-('Esc. 3 - F. Acumulable'!CD28) -> #REF! | S29: =+'Esc. 3 - F. Acumulable'!CD25 -> 200 | T29: =+'Esc. 3 - F. Acumulable'!CD16 -> 514 | V29: 2051 | W29: =+'Esc. 4 - F. Multiplicador'!CD33 -> 16.865563 | X29: =+'Esc. 4 - F. Multiplicador'!CD23 -> 0 | Y29: =+-'Esc. 4 - F. Multiplicador'!CD28 -> 0 | Z29: =+'Esc. 4 - F. Multiplicador'!CD25 -> 100 | AA29: =+'Esc. 4 - F. Multiplicador'!CD16 -> 100
A30: 2052 | B30: =+'Esc. 1 - Préstamos'!CG33 -> #REF! | C30: =+'Esc. 1 - Préstamos'!CG23 -> 804 | D30: =+-'Esc. 1 - Préstamos'!CG28 -> #REF! | E30: =+'Esc. 1 - Préstamos'!CG25 -> 100 | F30: =+'Esc. 1 - Préstamos'!CG25+'Esc. 1 - Préstamos'!CG27 -> 100 | H30: 2052 | I30: =+'Esc. 2 - F. Propios'!CG33 -> #REF! | J30: =+'Esc. 2 - F. Propios'!CG23 -> 0 | K30: =+-('Esc. 2 - F. Propios'!CG28) -> #REF! | L30: =+'Esc. 2 - F. Propios'!CG25 -> 100 | M30: =+'Esc. 2 - F. Propios'!CG25+'Esc. 2 - F. Propios'!CG27 -> 100 | O30: 2052 | P30: =+'Esc. 3 - F. Acumulable'!CG33 -> #REF! | Q30: =+'Esc. 3 - F. Acumulable'!CG23 -> 0 | R30: =+-('Esc. 3 - F. Acumulable'!CG28) -> #REF! | S30: =+'Esc. 3 - F. Acumulable'!CG25 -> 200 | T30: =+'Esc. 3 - F. Acumulable'!CG16 -> 514 | V30: 2052 | W30: =+'Esc. 4 - F. Multiplicador'!CG33 -> 16.965016 | X30: =+'Esc. 4 - F. Multiplicador'!CG23 -> 0 | Y30: =+-'Esc. 4 - F. Multiplicador'!CG28 -> 0 | Z30: =+'Esc. 4 - F. Multiplicador'!CG25 -> 100 | AA30: =+'Esc. 4 - F. Multiplicador'!CG16 -> 100
A31: 2053 | B31: =+'Esc. 1 - Préstamos'!CJ33 -> #REF! | C31: =+'Esc. 1 - Préstamos'!CJ23 -> 804 | D31: =+-'Esc. 1 - Préstamos'!CJ28 -> #REF! | E31: =+'Esc. 1 - Préstamos'!CJ25 -> 100 | F31: =+'Esc. 1 - Préstamos'!CJ25+'Esc. 1 - Préstamos'!CJ27 -> 100 | H31: 2053 | I31: =+'Esc. 2 - F. Propios'!CJ33 -> #REF! | J31: =+'Esc. 2 - F. Propios'!CJ23 -> 0 | K31: =+-('Esc. 2 - F. Propios'!CJ28) -> #REF! | L31: =+'Esc. 2 - F. Propios'!CJ25 -> 100 | M31: =+'Esc. 2 - F. Propios'!CJ25+'Esc. 2 - F. Propios'!CJ27 -> 100 | O31: 2053 | P31: =+'Esc. 3 - F. Acumulable'!CJ33 -> #REF! | Q31: =+'Esc. 3 - F. Acumulable'!CJ23 -> 0 | R31: =+-('Esc. 3 - F. Acumulable'!CJ28) -> #REF! | S31: =+'Esc. 3 - F. Acumulable'!CJ25 -> 200 | T31: =+'Esc. 3 - F. Acumulable'!CJ16 -> 514 | V31: 2053 | W31: =+'Esc. 4 - F. Multiplicador'!CJ33 -> 17.011943 | X31: =+'Esc. 4 - F. Multiplicador'!CJ23 -> 0 | Y31: =+-'Esc. 4 - F. Multiplicador'!CJ28 -> 0 | Z31: =+'Esc. 4 - F. Multiplicador'!CJ25 -> 100 | AA31: =+'Esc. 4 - F. Multiplicador'!CJ16 -> 100
A32: 2054 | B32: =+'Esc. 1 - Préstamos'!CM33 -> #REF! | C32: =+'Esc. 1 - Préstamos'!CM23 -> 804 | D32: =+-'Esc. 1 - Préstamos'!CM28 -> #REF! | E32: =+'Esc. 1 - Préstamos'!CM25 -> 100 | F32: =+'Esc. 1 - Préstamos'!CM25+'Esc. 1 - Préstamos'!CM27 -> 100 | H32: 2054 | I32: =+'Esc. 2 - F. Propios'!CM33 -> #REF! | J32: =+'Esc. 2 - F. Propios'!CM23 -> 0 | K32: =+-('Esc. 2 - F. Propios'!CM28) -> #REF! | L32: =+'Esc. 2 - F. Propios'!CM25 -> 100 | M32: =+'Esc. 2 - F. Propios'!CM25+'Esc. 2 - F. Propios'!CM27 -> 100 | O32: 2054 | P32: =+'Esc. 3 - F. Acumulable'!CM33 -> #REF! | Q32: =+'Esc. 3 - F. Acumulable'!CM23 -> 0 | R32: =+-('Esc. 3 - F. Acumulable'!CM28) -> #REF! | S32: =+'Esc. 3 - F. Acumulable'!CM25 -> 200 | T32: =+'Esc. 3 - F. Acumulable'!CM16 -> 514 | V32: 2054 | W32: =+'Esc. 4 - F. Multiplicador'!CM33 -> 17.085927 | X32: =+'Esc. 4 - F. Multiplicador'!CM23 -> 0 | Y32: =+-'Esc. 4 - F. Multiplicador'!CM28 -> 0 | Z32: =+'Esc. 4 - F. Multiplicador'!CM25 -> 100 | AA32: =+'Esc. 4 - F. Multiplicador'!CM16 -> 100
A33: 2055 | B33: =+'Esc. 1 - Préstamos'!CP33 -> #REF! | C33: =+'Esc. 1 - Préstamos'!CP23 -> 804 | D33: =+-'Esc. 1 - Préstamos'!CP28 -> #REF! | E33: =+'Esc. 1 - Préstamos'!CP25 -> 100 | F33: =+'Esc. 1 - Préstamos'!CP25+'Esc. 1 - Préstamos'!CP27 -> 100 | H33: 2055 | I33: =+'Esc. 2 - F. Propios'!CP33 -> #REF! | J33: =+'Esc. 2 - F. Propios'!CP23 -> 0 | K33: =+-('Esc. 2 - F. Propios'!CP28) -> #REF! | L33: =+'Esc. 2 - F. Propios'!CP25 -> 100 | M33: =+'Esc. 2 - F. Propios'!CP25+'Esc. 2 - F. Propios'!CP27 -> 100 | O33: 2055 | P33: =+'Esc. 3 - F. Acumulable'!CP33 -> #REF! | Q33: =+'Esc. 3 - F. Acumulable'!CP23 -> 0 | R33: =+-('Esc. 3 - F. Acumulable'!CP28) -> #REF! | S33: =+'Esc. 3 - F. Acumulable'!CP25 -> 200 | T33: =+'Esc. 3 - F. Acumulable'!CP16 -> 514 | V33: 2055 | W33: =+'Esc. 4 - F. Multiplicador'!CP33 -> 17.160445 | X33: =+'Esc. 4 - F. Multiplicador'!CP23 -> 0 | Y33: =+-'Esc. 4 - F. Multiplicador'!CP28 -> 0 | Z33: =+'Esc. 4 - F. Multiplicador'!CP25 -> 100 | AA33: =+'Esc. 4 - F. Multiplicador'!CP16 -> 100
A34: 2056 | B34: =+'Esc. 1 - Préstamos'!CS33 -> #REF! | C34: =+'Esc. 1 - Préstamos'!CS23 -> 804 | D34: =+-'Esc. 1 - Préstamos'!CS28 -> #REF! | E34: =+'Esc. 1 - Préstamos'!CS25 -> 100 | F34: =+'Esc. 1 - Préstamos'!CS25+'Esc. 1 - Préstamos'!CS27 -> 100 | H34: 2056 | I34: =+'Esc. 2 - F. Propios'!CS33 -> #REF! | J34: =+'Esc. 2 - F. Propios'!CS23 -> 0 | K34: =+-('Esc. 2 - F. Propios'!CS28) -> #REF! | L34: =+'Esc. 2 - F. Propios'!CS25 -> 100 | M34: =+'Esc. 2 - F. Propios'!CS25+'Esc. 2 - F. Propios'!CS27 -> 100 | O34: 2056 | P34: =+'Esc. 3 - F. Acumulable'!CS33 -> #REF! | Q34: =+'Esc. 3 - F. Acumulable'!CS23 -> 0 | R34: =+-('Esc. 3 - F. Acumulable'!CS28) -> #REF! | S34: =+'Esc. 3 - F. Acumulable'!CS25 -> 200 | T34: =+'Esc. 3 - F. Acumulable'!CS16 -> 514 | V34: 2056 | W34: =+'Esc. 4 - F. Multiplicador'!CS33 -> 17.262802 | X34: =+'Esc. 4 - F. Multiplicador'!CS23 -> 0 | Y34: =+-'Esc. 4 - F. Multiplicador'!CS28 -> 0 | Z34: =+'Esc. 4 - F. Multiplicador'!CS25 -> 100 | AA34: =+'Esc. 4 - F. Multiplicador'!CS16 -> 100
A35: 2057 | B35: =+'Esc. 1 - Préstamos'!CV33 -> #REF! | C35: =+'Esc. 1 - Préstamos'!CV23 -> 765.6 | D35: =+-'Esc. 1 - Préstamos'!CV28 -> #REF! | E35: =+'Esc. 1 - Préstamos'!CV25 -> 100 | F35: =+'Esc. 1 - Préstamos'!CV25+'Esc. 1 - Préstamos'!CV27 -> 100 | H35: 2057 | I35: =+'Esc. 2 - F. Propios'!CV33 -> #REF! | J35: =+'Esc. 2 - F. Propios'!CV23 -> 0 | K35: =+-('Esc. 2 - F. Propios'!CV28) -> #REF! | L35: =+'Esc. 2 - F. Propios'!CV25 -> 100 | M35: =+'Esc. 2 - F. Propios'!CV25+'Esc. 2 - F. Propios'!CV27 -> 100 | O35: 2057 | P35: =+'Esc. 3 - F. Acumulable'!CV33 -> #REF! | Q35: =+'Esc. 3 - F. Acumulable'!CV23 -> 0 | R35: =+-('Esc. 3 - F. Acumulable'!CV28) -> #REF! | S35: =+'Esc. 3 - F. Acumulable'!CV25 -> 200 | T35: =+'Esc. 3 - F. Acumulable'!CV16 -> 514 | V35: 2057 | W35: =+'Esc. 4 - F. Multiplicador'!CV33 -> 17.311099 | X35: =+'Esc. 4 - F. Multiplicador'!CV23 -> 0 | Y35: =+-'Esc. 4 - F. Multiplicador'!CV28 -> 0 | Z35: =+'Esc. 4 - F. Multiplicador'!CV25 -> 100 | AA35: =+'Esc. 4 - F. Multiplicador'!CV16 -> 100
Q38: 528
A39: Fondo (MMUSD) corresponde a la suma entre Gastos RSA y Gastos de Inversión Acumulables

Sheet Anexo c
C1: COSTO UNITARIO DEL SERVICIO DE ELECTRICIDAD (TARIFA)
C2: Simulaciones
H5: 2026 | K5: 2027 | N5: 2028 | Q5: 2029 | T5: 2030 | W5: 2031 | AA5: 2032 | AD5: 2033 | AG5: 2034 | AJ5: 2035 | AM5: 2036 | AP5: 2037 | AS5: 2038 | AV5: 2039 | AY5: 2040 | BB5: 2041 | BE5: 2042 | BH5: 2043 | BK5: 2044 | BN5: 2045 | BQ5: 2046 | BT5: 2047 | BW5: 2048 | BZ5: 2049 | CC5: 2050 | CF5: 2051 | CI5: 2052 | CL5: 2053 | CO5: 2054 | CR5: 2055 | CU5: 2056 | CX5: 2057
C6: FA Cargas Anexo C | H6: 2.7304387 | K6: 2.7501519 | N6: 2.8205668 | Q6: 2.8927846 | T6: 2.9668514 | W6: 3.0428147 | AA6: 3.1207229 | AD6: 2.8714563 | AG6: 2.8921876 | AJ6: 2.9130686 | AM6: 2.9341004 | AP6: 2.955284 | AS6: 2.9766206 | AV6: 2.9981112 | AY6: 3.019757 | BB6: 3.041559 | BE6: 3.0635184 | BH6: 3.0856364 | BK6: 3.1079141 | BN6: 3.1303526 | BQ6: 3.1529532 | BT6: 3.1757168 | BW6: 3.1986449 | BZ6: 3.2217385 | CC6: 3.2449988 | CF6: 3.268427 | CI6: 3.2920244 | CL6: 3.3157922 | CO6: 3.3397315 | CR6: 3.3638437 | CU6: 3.38813 | CX6: 3.4125916
C7: FA Utilidades de Capital | H7: 5.2754723 | K7: 5.3135601 | N7: 5.4496085 | Q7: 5.5891403 | T7: 5.7322447 | W7: 5.8790131 | AA7: 6.0295393 | AD7: 5.547932 | AG7: 5.5879869 | AJ7: 5.6283311 | AM7: 5.6689665 | AP7: 5.7098953 | AS7: 5.7511196 | AV7: 5.7926416 | AY7: 5.8344633 | BB7: 5.8765869 | BE7: 5.9190147 | BH7: 5.9617488 | BK7: 6.0047914 | BN7: 6.0481448 | BQ7: 6.0918112 | BT7: 6.1357929 | BW7: 6.1800921 | BZ7: 6.2247111 | CC7: 6.2696523 | CF7: 6.3149179 | CI7: 6.3605104 | CL7: 6.406432 | CO7: 6.4526851 | CR7: 6.4992722 | CU7: 6.5461957 | CX7: 6.5934579
C8: Energía Garantizada (GWh) | H8: 75134.52 | K8: 75134.52 | N8: 75340.368 | Q8: 75134.52 | T8: 75134.52 | W8: 75134.52 | AA8: 75340.368 | AD8: 75134.52 | AG8: 75134.52 | AJ8: 75134.52 | AM8: 75340.368 | AP8: 75134.52 | AS8: 75134.52 | AV8: 75134.52 | AY8: 75340.368 | BB8: 75134.52 | BE8: 75134.52 | BH8: 75134.52 | BK8: 75340.368 | BN8: 75134.52 | BQ8: 75134.52 | BT8: 75134.52 | BW8: 75340.368 | BZ8: 75134.52 | CC8: 75134.52 | CF8: 75134.52 | CI8: 75340.368 | CL8: 75134.52 | CO8: 75134.52 | CR8: 75134.52 | CU8: 75340.368 | CX8: 75134.52
C9: Potencia mensual disponible (MW) | H9: 12135 | K9: 12135 | N9: 12135 | Q9: 12135 | T9: 12135 | W9: 12135 | AA9: 12135 | AD9: 12135 | AG9: 12135 | AJ9: 12135 | AM9: 12135 | AP9: 12135 | AS9: =+'Nuevas Inst.'!B24 -> 12215 | AV9: =+'Nuevas Inst.'!B25 -> 12295 | AY9: =+'Nuevas Inst.'!B26 -> 12375 | BB9: =+'Nuevas Inst.'!B27 -> 12455 | BE9: =+'Nuevas Inst.'!B28 -> 12535 | BH9: =+'Nuevas Inst.'!B29 -> 12615 | BK9: =+'Nuevas Inst.'!B30 -> 12695 | BN9: =+'Nuevas Inst.'!B31 -> 12775 | BQ9: =+'Nuevas Inst.'!B32 -> 12855 | BT9: =+'Nuevas Inst.'!B33 -> 12935 | BW9: =+BT9 -> 12935 | BZ9: =+BT9 -> 12935 | CC9: =+BT9 -> 12935 | CF9: =+BT9 -> 12935 | CI9: =+BT9 -> 12935 | CL9: =+BT9 -> 12935 | CO9: =+BT9 -> 12935 | CR9: =+BT9 -> 12935 | CU9: =+BT9 -> 12935 | CX9: =+BT9 -> 12935
C10: Energía Cedida (GWh) | H10: 11670 | K10: 11670 | N10: 11670 | Q10: 11670 | T10: 11670 | W10: 11670 | AA10: 11670 | AD10: 11670 | AG10: 11670 | AJ10: 11670 | AM10: 11670 | AP10: 11670 | AS10: 11670 | AV10: 11670 | AY10: 11670 | BB10: 11670 | BE10: 11670 | BH10: 11670 | BK10: 11670 | BN10: 11670 | BQ10: 11670 | BT10: 11670 | BW10: 11670 | BZ10: 11670 | CC10: 11670 | CF10: 11670 | CI10: 11670 | CL10: 11670 | CO10: 11670 | CR10: 11670 | CU10: 11670 | CX10: 11670
K12: FM | N12: FM | Q12: FM | T12: FM | W12: FM | AA12: FM | AD12: FM | AG12: FM | AJ12: FM | AM12: FM | AP12: FM | AS12: FM | AV12: FM | AY12: FM | BB12: FM | BE12: FM | BH12: FM | BK12: FM | BN12: FM | BQ12: FM | BT12: FM | BW12: FM | BZ12: FM | CC12: FM | CF12: FM | CI12: FM | CL12: FM | CO12: FM | CR12: FM | CU12: FM | CX12: FM
K13: 4 | N13: 4 | Q13: 4 | T13: 4 | W13: =+T13 -> 4 | AA13: =+T13 -> 4 | AD13: =+T13 -> 4 | AG13: =+T13 -> 4 | AJ13: =+AG13 -> 4 | AM13: =+AG13 -> 4 | AP13: =+AG13 -> 4 | AS13: =+AG13 -> 4 | AV13: =+AG13 -> 4 | AY13: =+AG13 -> 4 | BB13: =+AG13 -> 4 | BE13: =+AG13 -> 4 | BH13: =+AG13 -> 4 | BK13: =+AG13 -> 4 | BN13: =+AG13 -> 4 | BQ13: =+AG13 -> 4 | BT13: =+AG13 -> 4 | BW13: =+AG13 -> 4 | BZ13: =+AG13 -> 4 | CC13: =+AG13 -> 4 | CF13: =+AG13 -> 4 | CI13: =+AG13 -> 4 | CL13: =+AG13 -> 4 | CO13: =+AG13 -> 4 | CR13: =+AG13 -> 4 | CU13: =+AG13 -> 4 | CX13: =+AG13 -> 4
H15: 2026 | K15: 2027 | N15: 2028 | Q15: 2029 | T15: 2030 | W15: 2031 | AA15: 2032 | AD15: 2033 | AG15: 2034 | AJ15: 2035 | AM15: 2036 | AP15: 2037 | AS15: 2038 | AV15: 2039 | AY15: 2040 | BB15: 2041 | BE15: 2042 | BH15: 2043 | BK15: 2044 | BN15: 2045 | BQ15: 2046 | BT15: 2047 | BW15: 2048 | BZ15: 2049 | CC15: 2050 | CF15: 2051 | CI15: 2052 | CL15: 2053 | CO15: 2054 | CR15: 2055 | CU15: 2056 | CX15: 2057
C16: Componentes | H16: MMUSD | I16: % | K16: MMUSD | L16: % | N16: MMUSD | O16: % | Q16: MMUSD | R16: % | T16: MMUSD | U16: % | W16: MMUSD | X16: % | AA16: MMUSD | AB16: % | AD16: MMUSD | AE16: % | AG16: MMUSD | AH16: % | AJ16: MMUSD | AK16: % | AM16: MMUSD | AN16: % | AP16: MMUSD | AQ16: % | AS16: MMUSD | AT16: % | AV16: MMUSD | AW16: % | AY16: MMUSD | AZ16: % | BB16: MMUSD | BC16: % | BE16: MMUSD | BF16: % | BH16: MMUSD | BI16: % | BK16: MMUSD | BL16: % | BN16: MMUSD | BO16: % | BQ16: MMUSD | BR16: % | BT16: MMUSD | BU16: % | BW16: MMUSD | BX16: % | BZ16: MMUSD | CA16: % | CC16: MMUSD | CD16: % | CF16: MMUSD | CG16: % | CI16: MMUSD | CJ16: % | CL16: MMUSD | CM16: % | CO16: MMUSD | CP16: % | CR16: MMUSD | CS16: % | CU16: MMUSD | CV16: % | CX16: MMUSD | CY16: %
A17: III.1 | C17: Utilidades del Capital | H17: =(100000*12%)*H7/1000 -> 63.305667 | I17: =+H17/H28 -> 0.022548558 | K17: =(100000*12%)*K7/1000 -> 63.762722 | L17: =+K17/K28 -> 0.029641307 | N17: =(100000*12%)*N7/1000 -> 65.395302 | O17: =+N17/N28 -> 0.027217083 | Q17: =(100000*12%)*Q7/1000 -> 67.069684 | R17: =+Q17/Q28 -> 0.027913949 | T17: =(100000*12%)*T7/1000 -> 68.786936 | U17: =+T17/T28 -> 0.028628658 | W17: =(100000*12%)*W7/1000 -> 70.548157 | X17: =+W17/W28 -> 0.029361666 | AA17: =(100000*12%)*AA7/1000 -> 72.354472 | AB17: =+AA17/AA28 -> 0.030113442 | AD17: =(100000*12%)*AD7/1000 -> 66.575184 | AE17: =+AD17/AD28 -> #REF! | AG17: =(100000*12%)*AG7/1000 -> 67.055843 | AH17: =+AG17/AG28 -> #REF! | AJ17: =(100000*12%)*AJ7/1000 -> 67.539973 | AK17: =+AJ17/AJ28 -> #REF! | AM17: =(100000*12%)*AM7/1000 -> 68.027598 | AN17: =+AM17/AM28 -> #REF! | AP17: =(100000*12%)*AP7/1000 -> 68.518744 | AQ17: =+AP17/AP28 -> #REF! | AS17: =(100000*12%)*AS7/1000 -> 69.013435 | AT17: =+AS17/AS28 -> #REF! | AV17: =(100000*12%)*AV7/1000 -> 69.511699 | AW17: =+AV17/AV28 -> #REF! | AY17: =(100000*12%)*AY7/1000 -> 70.013559 | AZ17: =+AY17/AY28 -> #REF! | BB17: =(100000*12%)*BB7/1000 -> 70.519043 | BC17: =+BB17/BB28 -> #REF! | BE17: =(100000*12%)*BE7/1000 -> 71.028176 | BF17: =+BE17/BE28 -> #REF! | BH17: =(100000*12%)*BH7/1000 -> 71.540986 | BI17: =+BH17/BH28 -> #REF! | BK17: =(100000*12%)*BK7/1000 -> 72.057497 | BL17: =+BK17/BK28 -> #REF! | BN17: =(100000*12%)*BN7/1000 -> 72.577738 | BO17: =+BN17/BN28 -> #REF! | BQ17: =(100000*12%)*BQ7/1000 -> 73.101735 | BR17: =+BQ17/BQ28 -> #REF! | BT17: =(100000*12%)*BT7/1000 -> 73.629515 | BU17: =+BT17/BT28 -> #REF! | BW17: =(100000*12%)*BW7/1000 -> 74.161105 | BX17: =+BW17/BW28 -> #REF! | BZ17: =(100000*12%)*BZ7/1000 -> 74.696533 | CA17: =+BZ17/BZ28 -> #REF! | CC17: =(100000*12%)*CC7/1000 -> 75.235827 | CD17: =+CC17/CC28 -> #REF! | CF17: =(100000*12%)*CF7/1000 -> 75.779015 | CG17: =+CF17/CF28 -> #REF! | CI17: =(100000*12%)*CI7/1000 -> 76.326124 | CJ17: =+CI17/CI28 -> #REF! | CL17: =(100000*12%)*CL7/1000 -> 76.877184 | CM17: =+CL17/CL28 -> #REF! | CO17: =(100000*12%)*CO7/1000 -> 77.432222 | CP17: =+CO17/CO28 -> #REF! | CR17: =(100000*12%)*CR7/1000 -> 77.991267 | CS17: =+CR17/CR28 -> #REF! | CU17: =(100000*12%)*CU7/1000 -> 78.554348 | CV17: =+CU17/CU28 -> #REF! | CX17: =(100000*12%)*CX7/1000 -> 79.121495 | CY17: =+CX17/CX28 -> #REF!
A18: III.5 | C18: Resarcimiento Cargas de Administración y Supervisión | H18: =50*4*H8*H6/1000000 -> 41.03004 | I18: =+H18/H28 -> 0.014614303 | K18: =50*K13*K8*K6/1000000 -> 41.326269 | L18: =+K18/K28 -> 0.019211298 | N18: =50*N13*N8*N6/1000000 -> 42.500508 | O18: =+N18/N28 -> 0.017688424 | Q18: =50*Q13*Q8*Q6/1000000 -> 43.469596 | R18: =+Q18/Q28 -> 0.018091752 | T18: =50*T13*T8*T6/1000000 -> 44.582592 | U18: =+T18/T28 -> 0.018554974 | W18: =50*W13*W8*W6/1000000 -> 45.724084 | X18: =+W18/W28 -> 0.019030055 | AA18: =50*AA13*AA8*AA6/1000000 -> 47.023283 | AB18: =+AA18/AA28 -> 0.019570773 | AD18: =50*AD13*AD8*AD6/1000000 -> 43.149098 | AE18: =+AD18/AD28 -> #REF! | AG18: =50*AG13*AG8*AG6/1000000 -> 43.460626 | AH18: =+AG18/AG28 -> #REF! | AJ18: =50*AJ13*AJ8*AJ6/1000000 -> 43.774403 | AK18: =+AJ18/AJ28 -> #REF! | AM18: =50*AM13*AM8*AM6/1000000 -> 44.211241 | AN18: =+AM18/AM28 -> #REF! | AP18: =50*AP13*AP8*AP6/1000000 -> 44.408769 | AQ18: =+AP18/AP28 -> #REF! | AS18: =50*AS13*AS8*AS6/1000000 -> 44.729392 | AT18: =+AS18/AS28 -> #REF! | AV18: =50*AV13*AV8*AV6/1000000 -> 45.052329 | AW18: =+AV18/AV28 -> #REF! | AY18: =50*AY13*AY8*AY6/1000000 -> 45.50192 | AZ18: =+AY18/AY28 -> #REF! | BB18: =50*BB13*BB8*BB6/1000000 -> 45.705215 | BC18: =+BB18/BB28 -> #REF! | BE18: =50*BE13*BE8*BE6/1000000 -> 46.035198 | BF18: =+BE18/BE28 -> #REF! | BH18: =50*BH13*BH8*BH6/1000000 -> 46.367563 | BI18: =+BH18/BH28 -> #REF! | BK18: =50*BK13*BK8*BK6/1000000 -> 46.830279 | BL18: =+BK18/BK28 -> #REF! | BN18: =50*BN13*BN8*BN6/1000000 -> 47.039509 | BO18: =+BN18/BN28 -> #REF! | BQ18: =50*BQ13*BQ8*BQ6/1000000 -> 47.379124 | BR18: =+BQ18/BQ28 -> #REF! | BT18: =50*BT13*BT8*BT6/1000000 -> 47.721192 | BU18: =+BT18/BT28 -> #REF! | BW18: =50*BW13*BW8*BW6/1000000 -> 48.197417 | BX18: =+BW18/BW28 -> #REF! | BZ18: =50*BZ13*BZ8*BZ6/1000000 -> 48.412755 | CA18: =+BZ18/BZ28 -> #REF! | CC18: =50*CC13*CC8*CC6/1000000 -> 48.762285 | CD18: =+CC18/CC28 -> #REF! | CF18: =50*CF13*CF8*CF6/1000000 -> 49.114339 | CG18: =+CF18/CF28 -> #REF! | CI18: =50*CI13*CI8*CI6/1000000 -> 49.604466 | CJ18: =+CI18/CI28 -> #REF! | CL18: =50*CL13*CL8*CL6/1000000 -> 49.82609 | CM18: =+CL18/CL28 -> #REF! | CO18: =50*CO13*CO8*CO6/1000000 -> 50.185825 | CP18: =+CO18/CO28 -> #REF! | CR18: =50*CR13*CR8*CR6/1000000 -> 50.548157 | CS18: =+CR18/CR28 -> #REF! | CU18: =50*CU13*CU8*CU6/1000000 -> 51.052592 | CV18: =+CU18/CU28 -> #REF! | CX18: =50*CX13*CX8*CX6/1000000 -> 51.280687 | CY18: =+CX18/CX28 -> #REF!
A19: III.4 | C19: Royalties | H19: =650*4*H8*H6/1000000 -> 533.39052 | I19: =+H19/H28 -> 0.18998594 | K19: =650*K13*K8*K6/1000000 -> 537.24149 | L19: =+K19/K28 -> 0.24974687 | N19: =650*N13*N8*N6/1000000 -> 552.5066 | O19: =+N19/N28 -> 0.22994952 | Q19: =650*Q13*Q8*Q6/1000000 -> 565.10475 | R19: =+Q19/Q28 -> 0.23519278 | T19: =650*T13*T8*T6/1000000 -> 579.57369 | U19: =+T19/T28 -> 0.24121466 | W19: =650*W13*W8*W6/1000000 -> 594.4131 | X19: =+W19/W28 -> 0.24739072 | AA19: =650*AA13*AA8*AA6/1000000 -> 611.30268 | AB19: =+AA19/AA28 -> 0.25442005 | AD19: =650*AD13*AD8*AD6/1000000 -> 560.93827 | AE19: =+AD19/AD28 -> #REF! | AG19: =650*AG13*AG8*AG6/1000000 -> 564.98814 | AH19: =+AG19/AG28 -> #REF! | AJ19: =650*AJ13*AJ8*AJ6/1000000 -> 569.06724 | AK19: =+AJ19/AJ28 -> #REF! | AM19: =650*AM13*AM8*AM6/1000000 -> 574.74613 | AN19: =+AM19/AM28 -> #REF! | AP19: =650*AP13*AP8*AP6/1000000 -> 577.314 | AQ19: =+AP19/AP28 -> #REF! | AS19: =650*AS13*AS8*AS6/1000000 -> 581.48209 | AT19: =+AS19/AS28 -> #REF! | AV19: =650*AV13*AV8*AV6/1000000 -> 585.68028 | AW19: =+AV19/AV28 -> #REF! | AY19: =650*AY13*AY8*AY6/1000000 -> 591.52496 | AZ19: =+AY19/AY28 -> #REF! | BB19: =650*BB13*BB8*BB6/1000000 -> 594.1678 | BC19: =+BB19/BB28 -> #REF! | BE19: =650*BE13*BE8*BE6/1000000 -> 598.45757 | BF19: =+BE19/BE28 -> #REF! | BH19: =650*BH13*BH8*BH6/1000000 -> 602.77831 | BI19: =+BH19/BH28 -> #REF! | BK19: =650*BK13*BK8*BK6/1000000 -> 608.79362 | BL19: =+BK19/BK28 -> #REF! | BN19: =650*BN13*BN8*BN6/1000000 -> 611.51361 | BO19: =+BN19/BN28 -> #REF! | BQ19: =650*BQ13*BQ8*BQ6/1000000 -> 615.92862 | BR19: =+BQ19/BQ28 -> #REF! | BT19: =650*BT13*BT8*BT6/1000000 -> 620.3755 | BU19: =+BT19/BT28 -> #REF! | BW19: =650*BW13*BW8*BW6/1000000 -> 626.56642 | BX19: =+BW19/BW28 -> #REF! | BZ19: =650*BZ13*BZ8*BZ6/1000000 -> 629.36581 | CA19: =+BZ19/BZ28 -> #REF! | CC19: =650*CC13*CC8*CC6/1000000 -> 633.90971 | CD19: =+CC19/CC28 -> #REF! | CF19: =650*CF13*CF8*CF6/1000000 -> 638.48641 | CG19: =+CF19/CF28 -> #REF! | CI19: =650*CI13*CI8*CI6/1000000 -> 644.85806 | CJ19: =+CI19/CI28 -> #REF! | CL19: =650*CL13*CL8*CL6/1000000 -> 647.73918 | CM19: =+CL19/CL28 -> #REF! | CO19: =650*CO13*CO8*CO6/1000000 -> 652.41572 | CP19: =+CO19/CO28 -> #REF! | CR19: =650*CR13*CR8*CR6/1000000 -> 657.12603 | CS19: =+CR19/CR28 -> #REF! | CU19: =650*CU13*CU8*CU6/1000000 -> 663.6837 | CV19: =+CU19/CU28 -> #REF! | CX19: =650*CX13*CX8*CX6/1000000 -> 666.64892 | CY19: =+CX19/CX28 -> #REF!
A20: III.2 y III.3 | C20: Servicio de la Deuda | H20: =26.7 -> 26.7 | I20: =+H20/H28 -> 0.0095101516 | K20: =24.81355084+169 -> 193.81355 | L20: =+K20/K28 -> 0.090097896 | N20: =18.3972455+169 -> 187.39725 | O20: =+N20/N28 -> 0.077993468 | Q20: =16.1114707+169 -> 185.11147 | R20: =+Q20/Q28 -> 0.077042144 | T20: =15.77515634+169 -> 184.77516 | U20: =+T20/T28 -> 0.076902172 | W20: =15.41982394+169 -> 184.41982 | X20: =+W20/W28 -> 0.076754285 | AA20: =15.0443975+169 -> 184.0444 | AB20: =+AA20/AA28 -> 0.076598035 | AD20: =17.2 -> 17.2 | AE20: =+AD20/AD28 -> #REF! | AG20: =17.2 -> 17.2 | AH20: =+AG20/AG28 -> #REF! | AJ20: =17.2 -> 17.2 | AK20: =+AJ20/AJ28 -> #REF! | AM20: =17.2 -> 17.2 | AN20: =+AM20/AM28 -> #REF! | AP20: =17.2 -> 17.2 | AQ20: =+AP20/AP28 -> #REF! | AS20: =17.2 -> 17.2 | AT20: =+AS20/AS28 -> #REF! | AV20: 0 | AW20: =+AV20/AV28 -> #REF! | AY20: 0 | AZ20: =+AY20/AY28 -> #REF! | BB20: 0 | BC20: =+BB20/BB28 -> #REF! | BE20: 0 | BF20: =+BE20/BE28 -> #REF! | BH20: 0 | BI20: =+BH20/BH28 -> #REF! | BK20: 0 | BL20: =+BK20/BK28 -> #REF! | BN20: 0 | BO20: =+BN20/BN28 -> #REF! | BQ20: 0 | BR20: =+BQ20/BQ28 -> #REF! | BT20: 0 | BU20: =+BT20/BT28 -> #REF! | BW20: 0 | BX20: =+BW20/BW28 -> #REF! | BZ20: 0 | CA20: =+BZ20/BZ28 -> #REF! | CC20: 0 | CD20: =+CC20/CC28 -> #REF! | CF20: 0 | CG20: =+CF20/CF28 -> #REF! | CI20: 0 | CJ20: =+CI20/CI28 -> #REF! | CL20: 0 | CM20: =+CL20/CL28 -> #REF! | CO20: 0 | CP20: =+CO20/CO28 -> #REF! | CR20: 0 | CS20: =+CR20/CR28 -> #REF! | CU20: 0 | CV20: =+CU20/CU28 -> #REF! | CX20: 0 | CY20: =+CX20/CX28 -> #REF!
A21: III.6 | C21: Gastos de Explotación e Inversiones | H21: =+H22+H23+H24 -> 2170.4 | I21: =+H21/H28 -> 0.77306491 | K21: =+K22+K23+K24 -> 1315 | L21: =+K21/K28 -> 0.61130263 | N21: =+N22+N23+N24 -> 1554.9303 | O21: =+N21/N28 -> 0.64715151 | Q21: =+Q22+Q23+Q24 -> 1541.9745 | R21: =+Q21/Q28 -> 0.64175937 | T21: =+T22+T23+T24 -> 1694.0116 | U21: =+T21/T28 -> 0.7050362 | W21: =+W22+W23+W24 -> 1676.6248 | X21: =+W21/W28 -> 0.69779994 | AA21: =+AA22+AA23+AA24 -> 1658.0052 | AB21: =+AA21/AA28 -> 0.69005056 | AD21: 950 | AE21: =+AD21/AD28 -> #REF! | AG21: 950 | AH21: =+AG21/AG28 -> #REF! | AJ21: 950 | AK21: =+AJ21/AJ28 -> #REF! | AM21: 950 | AN21: =+AM21/AM28 -> #REF! | AP21: 950 | AQ21: =+AP21/AP28 -> #REF! | AS21: 950 | AT21: =+AS21/AS28 -> #REF! | AV21: 950 | AW21: =+AV21/AV28 -> #REF! | AY21: 950 | AZ21: =+AY21/AY28 -> #REF! | BB21: 950 | BC21: =+BB21/BB28 -> #REF! | BE21: 950 | BF21: =+BE21/BE28 -> #REF! | BH21: 950 | BI21: =+BH21/BH28 -> #REF! | BK21: 950 | BL21: =+BK21/BK28 -> #REF! | BN21: 950 | BO21: =+BN21/BN28 -> #REF! | BQ21: 950 | BR21: =+BQ21/BQ28 -> #REF! | BT21: 950 | BU21: =+BT21/BT28 -> #REF! | BW21: 950 | BX21: =+BW21/BW28 -> #REF! | BZ21: 950 | CA21: =+BZ21/BZ28 -> #REF! | CC21: 950 | CD21: =+CC21/CC28 -> #REF! | CF21: 950 | CG21: =+CF21/CF28 -> #REF! | CI21: 950 | CJ21: =+CI21/CI28 -> #REF! | CL21: 950 | CM21: =+CL21/CL28 -> #REF! | CO21: 950 | CP21: =+CO21/CO28 -> #REF! | CR21: 950 | CS21: =+CR21/CR28 -> #REF! | CU21: 950 | CV21: =+CU21/CU28 -> #REF! | CX21: 950 | CY21: =+CX21/CX28 -> #REF!
C22: - Costos Operativos | H22: 870.4 | I22: 0.31002382 | K22: 960 | L22: 0.44550963 | N22: 993.4 | O22: 0.44992876 | Q22: 1011.3 | R22: 0.40543392 | T22: 1030 | U22: 0.42519317 | W22: 1058.5 | X22: 0.44690246 | AA22: 1094.3
C23: - Gastos Sociales | H23: 1300 | I23: =+H23/H28 -> 0.46304109 | K23: 200 | L23: =+K23/K28 -> 0.092973784 | N23: 200 | O23: =+N23/N28 -> 0.083238649 | Q23: 200 | R23: =+Q23/Q28 -> 0.083238649 | T23: 200 | U23: =+T23/T28 -> 0.083238649 | W23: 200 | X23: =+W23/W28 -> 0.083238649 | AA23: 200 | AB23: =+AA23/AA28 -> 0.083238649 | AD23: 200 | AE23: =+AD23/AD28 -> #REF! | AG23: 200 | AH23: =+AG23/AG28 -> #REF! | AJ23: 200 | AK23: =+AJ23/AJ28 -> #REF! | AM23: 200 | AN23: =+AM23/AM28 -> #REF! | AP23: 200 | AQ23: =+AP23/AP28 -> #REF! | AS23: 200 | AT23: =+AS23/AS28 -> #REF! | AV23: 200 | AW23: =+AV23/AV28 -> #REF! | AY23: 200 | AZ23: =+AY23/AY28 -> #REF! | BB23: 200 | BC23: =+BB23/BB28 -> #REF! | BE23: 200 | BF23: =+BE23/BE28 -> #REF! | BH23: 200 | BI23: =+BH23/BH28 -> #REF! | BK23: 200 | BL23: =+BK23/BK28 -> #REF! | BN23: 200 | BO23: =+BN23/BN28 -> #REF! | BQ23: 200 | BR23: =+BQ23/BQ28 -> #REF! | BT23: 200 | BU23: =+BT23/BT28 -> #REF! | BW23: 200 | BX23: =+BW23/BW28 -> #REF! | BZ23: 200 | CA23: =+BZ23/BZ28 -> #REF! | CC23: 200 | CD23: =+CC23/CC28 -> #REF! | CF23: 200 | CG23: =+CF23/CF28 -> #REF! | CI23: 200 | CJ23: =+CI23/CI28 -> #REF! | CL23: 200 | CM23: =+CL23/CL28 -> #REF! | CO23: 200 | CP23: =+CO23/CO28 -> #REF! | CR23: 200 | CS23: =+CR23/CR28 -> #REF! | CU23: 200 | CV23: =+CU23/CU28 -> #REF! | CX23: 200 | CY23: =+CX23/CX28 -> #REF!
C24: - Inversiones | I24: =+H24/H28 -> 0 | K24: 155 | L24: =+K24/K28 -> 0.072054682 | N24: 361.53034 | O24: =+N24/N28 -> 0.15046649 | Q24: 330.6745 | R24: =+Q24/Q28 -> 0.13762449 | T24: 464.01162 | U24: =+T24/T28 -> 0.1931185 | W24: 418.12484 | X24: =+W24/W28 -> 0.17402073 | AA24: 363.70517 | AB24: =+AA24/AA28 -> 0.15137164 | AD24: 400 | AE24: =+AD24/AD28 -> #REF! | AG24: 400 | AH24: =+AG24/AG28 -> #REF! | AJ24: 400 | AK24: =+AJ24/AJ28 -> #REF! | AM24: 400 | AN24: =+AM24/AM28 -> #REF! | AP24: 400 | AQ24: =+AP24/AP28 -> #REF! | AS24: 400 | AT24: =+AS24/AS28 -> #REF! | AV24: 400 | AW24: =+AV24/AV28 -> #REF! | AY24: 400 | AZ24: =+AY24/AY28 -> #REF! | BB24: 400 | BC24: =+BB24/BB28 -> #REF! | BE24: 400 | BF24: =+BE24/BE28 -> #REF! | BH24: 400 | BI24: =+BH24/BH28 -> #REF! | BK24: 400 | BL24: =+BK24/BK28 -> #REF! | BN24: 400 | BO24: =+BN24/BN28 -> #REF! | BQ24: 400 | BR24: =+BQ24/BQ28 -> #REF! | BT24: 400 | BU24: =+BT24/BT28 -> #REF! | BW24: 400 | BX24: =+BW24/BW28 -> #REF! | BZ24: 400 | CA24: =+BZ24/BZ28 -> #REF! | CC24: 400 | CD24: =+CC24/CC28 -> #REF! | CF24: 400 | CG24: =+CF24/CF28 -> #REF! | CI24: 400 | CJ24: =+CI24/CI28 -> #REF! | CL24: 400 | CM24: =+CL24/CL28 -> #REF! | CO24: 400 | CP24: =+CO24/CO28 -> #REF! | CR24: 400 | CS24: =+CR24/CR28 -> #REF! | CU24: 400 | CV24: =+CU24/CU28 -> #REF! | CX24: 400 | CY24: =+CX24/CX28 -> #REF!
A25: III.7 | C25: Saldo Cuenta de Explotación (SCE) | H25: =+H26+H27 -> -27.3 | I25: =+H25/H28 -> -0.0097238629 | K25: 0 | L25: =+K25/K28 -> 0 | N25: =+N26+N27 -> 0 | O25: =+N25/N28 -> 0 | Q25: =+Q26+Q27 -> 0 | R25: =+Q25/Q28 -> 0 | T25: =+T26+T27 -> -169 | U25: =+T25/T28 -> -0.070336659 | W25: =+W26+W27 -> -169 | X25: =+W25/W28 -> -0.070336659 | AA25: =+AA26+AA27 -> -170 | AB25: =+AA25/AA28 -> -0.070752852 | AD25: =+AD26+AD27 -> #REF! | AE25: =+AD25/AD28 -> #REF! | AG25: =+AG26+AG27 -> #REF! | AH25: =+AG25/AG28 -> #REF! | AJ25: =+AJ26+AJ27 -> #REF! | AK25: =+AJ25/AJ28 -> #REF! | AM25: =+AM26+AM27 -> #REF! | AN25: =+AM25/AM28 -> #REF! | AP25: =+AP26+AP27 -> #REF! | AQ25: =+AP25/AP28 -> #REF! | AS25: =+AS26+AS27 -> #REF! | AT25: =+AS25/AS28 -> #REF! | AV25: =+AV26+AV27 -> #REF! | AW25: =+AV25/AV28 -> #REF! | AY25: =+AY26+AY27 -> #REF! | AZ25: =+AY25/AY28 -> #REF! | BB25: =+BB26+BB27 -> #REF! | BC25: =+BB25/BB28 -> #REF! | BE25: =+BE26+BE27 -> #REF! | BF25: =+BE25/BE28 -> #REF! | BH25: =+BH26+BH27 -> #REF! | BI25: =+BH25/BH28 -> #REF! | BK25: =+BK26+BK27 -> #REF! | BL25: =+BK25/BK28 -> #REF! | BN25: =+BN26+BN27 -> #REF! | BO25: =+BN25/BN28 -> #REF! | BQ25: =+BQ26+BQ27 -> #REF! | BR25: =+BQ25/BQ28 -> #REF! | BT25: =+BT26+BT27 -> #REF! | BU25: =+BT25/BT28 -> #REF! | BW25: =+BW26+BW27 -> #REF! | BX25: =+BW25/BW28 -> #REF! | BZ25: =+BZ26+BZ27 -> #REF! | CA25: =+BZ25/BZ28 -> #REF! | CC25: =+CC26+CC27 -> #REF! | CD25: =+CC25/CC28 -> #REF! | CF25: =+CF26+CF27 -> #REF! | CG25: =+CF25/CF28 -> #REF! | CI25: =+CI26+CI27 -> #REF! | CJ25: =+CI25/CI28 -> #REF! | CL25: =+CL26+CL27 -> #REF! | CM25: =+CL25/CL28 -> #REF! | CO25: =+CO26+CO27 -> #REF! | CP25: =+CO25/CO28 -> #REF! | CR25: =+CR26+CR27 -> #REF! | CS25: =+CR25/CR28 -> #REF! | CU25: =+CU26+CU27 -> #REF! | CV25: =+CU25/CU28 -> #REF! | CX25: =+CX26+CX27 -> #REF! | CY25: =+CX25/CX28 -> #REF!
C26: - SCE Ejercicio Anterior | H26: -27.3
C27: - Ingreso por incremento de producción | I27: =+H27/H28 -> 0 | L27: =+K27/K28 -> 0 | T27: -169 | W27: -169 | AA27: -170 | AD27: =+'Increm. Producción'!N16 -> #REF! | AG27: =+'Increm. Producción'!O16 -> #REF! | AJ27: =+'Increm. Producción'!P16 -> #REF! | AM27: =+'Increm. Producción'!Q16 -> #REF! | AP27: =+'Increm. Producción'!R16 -> #REF! | AS27: =+'Increm. Producción'!S16 -> #REF! | AV27: =+'Increm. Producción'!T16 -> #REF! | AY27: =+'Increm. Producción'!U16 -> #REF! | BB27: =+'Increm. Producción'!V16 -> #REF! | BE27: =+'Increm. Producción'!W16 -> #REF! | BH27: =+'Increm. Producción'!X16 -> #REF! | BK27: =+'Increm. Producción'!Y16 -> #REF! | BN27: =+'Increm. Producción'!Z16 -> #REF! | BQ27: =+'Increm. Producción'!AA16 -> #REF! | BT27: =+'Increm. Producción'!AB16 -> #REF! | BW27: =+'Increm. Producción'!AC16 -> #REF! | BZ27: =+'Increm. Producción'!AD16 -> #REF! | CC27: =+'Increm. Producción'!AE16 -> #REF! | CF27: =+'Increm. Producción'!AF16 -> #REF! | CI27: =+'Increm. Producción'!AG16 -> #REF! | CL27: =+'Increm. Producción'!AH16 -> #REF! | CO27: =+'Increm. Producción'!AI16 -> #REF! | CR27: =+'Increm. Producción'!AJ16 -> #REF! | CU27: =+'Increm. Producción'!AK16 -> #REF! | CX27: =+'Increm. Producción'!AL16 -> #REF!
C28: TOTAL | H28: =+H17+H18+H19+H20+H21+H25 -> 2807.5262 | I28: =+I17+I18+I19+I20+I21+I23+#REF!+I24+I25 -> #REF! | K28: =+K17+K18+K19+K20+K21+K25 -> 2151.144 | L28: =+L17+L18+L19+L20+L21+L23+#REF!+L24+L25 -> #REF! | N28: =+N17+N18+N19+N20+N21+N25 -> 2402.73 | O28: =+O17+O18+O19+O20+O21+O23+#REF!+O24+O25 -> #REF! | Q28: =+Q17+Q18+Q19+Q20+Q21+Q25 -> 2402.73 | R28: =+R17+R18+R19+R20+R21+R23+#REF!+R24+R25 -> #REF! | T28: =+T17+T18+T19+T20+T21+T25 -> 2402.73 | U28: =+U17+U18+U19+U20+U21+U23+#REF!+U24+U25 -> #REF! | W28: =+W17+W18+W19+W20+W21+W25 -> 2402.73 | X28: =+X17+X18+X19+X20+X21+X23+#REF!+X24+X25 -> #REF! | AA28: =+AA17+AA18+AA19+AA20+AA21+AA25 -> 2402.73 | AB28: =+AB17+AB18+AB19+AB20+AB21+AB23+#REF!+AB24+AB25 -> #REF! | AD28: =+AD17+AD18+AD19+AD20+AD21+AD23+#REF!+AD24+AD25 -> #REF! | AE28: =+AE17+AE18+AE19+AE20+AE21+AE23+#REF!+AE24+AE25 -> #REF! | AG28: =+AG17+AG18+AG19+AG20+AG21+AG23+#REF!+AG24+AG25 -> #REF! | AH28: =+AH17+AH18+AH19+AH20+AH21+AH23+#REF!+AH24+AH25 -> #REF! | AJ28: =+AJ17+AJ18+AJ19+AJ20+AJ21+AJ23+#REF!+AJ24+AJ25 -> #REF! | AK28: =+AK17+AK18+AK19+AK20+AK21+AK23+#REF!+AK24+AK25 -> #REF! | AM28: =+AM17+AM18+AM19+AM20+AM21+AM23+#REF!+AM24+AM25 -> #REF! | AN28: =+AN17+AN18+AN19+AN20+AN21+AN23+#REF!+AN24+AN25 -> #REF! | AP28: =+AP17+AP18+AP19+AP20+AP21+AP23+#REF!+AP24+AP25 -> #REF! | AQ28: =+AQ17+AQ18+AQ19+AQ20+AQ21+AQ23+#REF!+AQ24+AQ25 -> #REF! | AS28: =+AS17+AS18+AS19+AS20+AS21+AS23+#REF!+AS24+AS25 -> #REF! | AT28: =+AT17+AT18+AT19+AT20+AT21+AT23+#REF!+AT24+AT25 -> #REF! | AV28: =+AV17+AV18+AV19+AV20+AV21+AV23+#REF!+AV24+AV25 -> #REF! | AW28: =+AW17+AW18+AW19+AW20+AW21+AW23+#REF!+AW24+AW25 -> #REF! | AY28: =+AY17+AY18+AY19+AY20+AY21+AY23+#REF!+AY24+AY25 -> #REF! | AZ28: =+AZ17+AZ18+AZ19+AZ20+AZ21+AZ23+#REF!+AZ24+AZ25 -> #REF! | BB28: =+BB17+BB18+BB19+BB20+BB21+BB23+#REF!+BB24+BB25 -> #REF! | BC28: =+BC17+BC18+BC19+BC20+BC21+BC23+#REF!+BC24+BC25 -> #REF! | BE28: =+BE17+BE18+BE19+BE20+BE21+BE23+#REF!+BE24+BE25 -> #REF! | BF28: =+BF17+BF18+BF19+BF20+BF21+BF23+#REF!+BF24+BF25 -> #REF! | BH28: =+BH17+BH18+BH19+BH20+BH21+BH23+#REF!+BH24+BH25 -> #REF! | BI28: =+BI17+BI18+BI19+BI20+BI21+BI23+#REF!+BI24+BI25 -> #REF! | BK28: =+BK17+BK18+BK19+BK20+BK21+BK23+#REF!+BK24+BK25 -> #REF! | BL28: =+BL17+BL18+BL19+BL20+BL21+BL23+#REF!+BL24+BL25 -> #REF! | BN28: =+BN17+BN18+BN19+BN20+BN21+BN23+#REF!+BN24+BN25 -> #REF! | BO28: =+BO17+BO18+BO19+BO20+BO21+BO23+#REF!+BO24+BO25 -> #REF! | BQ28: =+BQ17+BQ18+BQ19+BQ20+BQ21+BQ23+#REF!+BQ24+BQ25 -> #REF! | BR28: =+BR17+BR18+BR19+BR20+BR21+BR23+#REF!+BR24+BR25 -> #REF! | BT28: =+BT17+BT18+BT19+BT20+BT21+BT23+#REF!+BT24+BT25 -> #REF! | BU28: =+BU17+BU18+BU19+BU20+BU21+BU23+#REF!+BU24+BU25 -> #REF! | BW28: =+BW17+BW18+BW19+BW20+BW21+BW23+#REF!+BW24+BW25 -> #REF! | BX28: =+BX17+BX18+BX19+BX20+BX21+BX23+#REF!+BX24+BX25 -> #REF! | BZ28: =+BZ17+BZ18+BZ19+BZ20+BZ21+BZ23+#REF!+BZ24+BZ25 -> #REF! | CA28: =+CA17+CA18+CA19+CA20+CA21+CA23+#REF!+CA24+CA25 -> #REF! | CC28: =+CC17+CC18+CC19+CC20+CC21+CC23+#REF!+CC24+CC25 -> #REF! | CD28: =+CD17+CD18+CD19+CD20+CD21+CD23+#REF!+CD24+CD25 -> #REF! | CF28: =+CF17+CF18+CF19+CF20+CF21+CF23+#REF!+CF24+CF25 -> #REF! | CG28: =+CG17+CG18+CG19+CG20+CG21+CG23+#REF!+CG24+CG25 -> #REF! | CI28: =+CI17+CI18+CI19+CI20+CI21+CI23+#REF!+CI24+CI25 -> #REF! | CJ28: =+CJ17+CJ18+CJ19+CJ20+CJ21+CJ23+#REF!+CJ24+CJ25 -> #REF! | CL28: =+CL17+CL18+CL19+CL20+CL21+CL23+#REF!+CL24+CL25 -> #REF! | CM28: =+CM17+CM18+CM19+CM20+CM21+CM23+#REF!+CM24+CM25 -> #REF! | CO28: =+CO17+CO18+CO19+CO20+CO21+CO23+#REF!+CO24+CO25 -> #REF! | CP28: =+CP17+CP18+CP19+CP20+CP21+CP23+#REF!+CP24+CP25 -> #REF! | CR28: =+CR17+CR18+CR19+CR20+CR21+CR23+#REF!+CR24+CR25 -> #REF! | CS28: =+CS17+CS18+CS19+CS20+CS21+CS23+#REF!+CS24+CS25 -> #REF! | CU28: =+CU17+CU18+CU19+CU20+CU21+CU23+#REF!+CU24+CU25 -> #REF! | CV28: =+CV17+CV18+CV19+CV20+CV21+CV23+#REF!+CV24+CV25 -> #REF! | CX28: =+CX17+CX18+CX19+CX20+CX21+CX23+#REF!+CX24+CX25 -> #REF! | CY28: =+CY17+CY18+CY19+CY20+CY21+CY23+#REF!+CY24+CY25 -> #REF!
